Workbook

Sheet 📋 Instructions
B1: PM COMPETENCY QUESTIONNAIRE ASSESSMENT TOOL
B3: 📌 HOW THIS TOOL WORKS
B5: This questionnaire assesses competency through real-world scenarios — NOT by asking you to rate yourself.
B6: You will read 135 situational questions across 8 competency areas. Each question presents a workplace scenario
B7: and 4 possible responses (A, B, C, D). Select the option that BEST describes what you would actually do.
B9: ✅ IMPORTANT RULES FOR EMPLOYEES
B11: • Answer based on what you ACTUALLY do — not what you think the 'correct' answer is.
B12: • There are no trick questions. Your honest responses give the most useful picture.
B13: • Each response option reflects a different level of capability — you will not see scores.
B14: • The questionnaire takes approximately 30–45 minutes to complete.
B15: • Once submitted, scores are calculated automatically in the 'Results' sheet.
B17: 📊 QUESTIONNAIRE STRUCTURE
... B43: for HR/Line Manager use after the questionnaire is submitted.

Sheet 📝 Questionnaire
A1: PROJECT MANAGEMENT COMPETENCY QUESTIONNAIRE
A2: Select the option (A / B / C / D) that BEST describes your typical approach. Answer honestly — there are no right or wrong answers.
A4: Employee Name: | C4: Assessment Date:
A7: 1. ROOT CAUSE ANALYSIS & RISK ASSESSMENT
A9: Q1 | C9: A major project deliverable is consistently late. What is your first step? | D9: YOUR ANSWER ↓
A10: A | C10: A) Ask the team to work overtime to recover the delay | D10: C
A11: B | C11: B) Log the delay in the risk register and notify the sponsor
A12: C | C12: C) Conduct a structured root cause analysis (5-Whys or fishbone) to identify the real driver
A13: D | C13: D) Redesign the project schedule and present a systemic fix with predictive indicators to prevent recurrence
A15: Q2 | C15: During project execution a vendor fails to deliver. How do you respond? | D15: YOUR ANSWER ↓
A16: A | C16: A) Escalate immediately to senior management | D16: B
A17: B | C17: B) Document the issue and investigate the vendor's reason
A18: C | C18: C) Conduct a root cause review, trigger the contingency plan, and adjust the risk register
A19: D | C19: D) Lead a cross-functional risk response, implement lessons-learned and update organisational risk frameworks
A21: Q3 | C21: A risk you identified 3 months ago has now materialised. What does this indicate about your risk approach? | D21: YOUR ANSWER ↓
A22: A | C22: A) Risks are unpredictable; there is nothing more you could have done | D22: C
A23: B | C23: B) The risk register should be updated more frequently
A24: C | C24: C) Proactive monitoring and early-warning indicators were in place but response time needs improvement
A25: D | C25: D) The risk management strategy requires a full review; you implement a real-time risk intelligence system
A27: Q4 | C27: Before a project kicks off, how do you approach risk identification? | D27: YOUR ANSWER ↓
A28: A | C28: A) Wait until risks appear during execution | D28: D
A29: B | C29: B) Use a basic checklist from previous projects
A30: C | C30: C) Facilitate a structured risk workshop using SWOT and probability/impact matrices
A31: D | C31: D) Develop a comprehensive risk taxonomy aligned to organisational strategy with Monte Carlo simulations
A33: Q5 | C33: A key technical assumption in your project is challenged by a stakeholder late in planning. What do you do? | D33: YOUR ANSWER ↓
A34: A | C34: A) Dismiss it since planning is already done | D34: B
A35: B | C35: B) Log it as an issue and note it for later review
A36: C | C36: C) Re-evaluate the assumption formally, update the risk register, and communicate impact to the team
A37: D | C37: D) Integrate assumption management into project governance and present scenario analysis to leadership
A39: Q6 | C39: What best describes how you prevent project failure proactively? | D39: YOUR ANSWER ↓
A40: A | C40: A) React to problems as they arise | D40: D
A41: B | C41: B) Review lessons learned from past projects before starting a new one
A42: C | C42: C) Build pre-mortems, stress tests, and early warning dashboards into every project plan
A43: D | C43: D) Lead organisational failure prevention programmes and embed risk intelligence in project culture
A45: Q7 | C45: A scope change request arrives mid-project. How do you assess its impact? | D45: YOUR ANSWER ↓
A46: A | C46: A) Accept the change if the client requests it | D46: A
A47: B | C47: B) Informally discuss impact with the project team
A48: C | C48: C) Conduct an integrated impact analysis covering cost, time, quality, and risks; update all affected plans
A49: D | C49: D) Develop a strategic impact model linking scope changes to portfolio-level risks and executive decision frameworks
A51: Q8 | C51: Two project risks appear to be interdependent. What do you do? | D51: YOUR ANSWER ↓
...

Sheet 📊 Results & Competency Map
A1: PM COMPETENCY QUESTIONNAIRE — RESULTS & COMPETENCY MAP
A2: Auto-calculated from questionnaire responses | Competency Scale: 1=Amateur 2=Collaborator 3=Enabler 4=Driving Force
A4: # | B4: Sub-Code | C4: Sub-Competency Name | D4: Competency Area | E4: Q1 Score | F4: Q2 Score | G4: Q3 Score | H4: Avg Score | I4: Competency Level
A6: 1. Root Cause Analysis & Risk Assessment
A7: 1 | B7: 1.1 | C7: Root Cause & Risk Management Mastery | D7: Root Cause Analysis & Risk Assessment | E7: =IFERROR(CHOOSE(MATCH('📝 Questionnaire'!D10,{"A","B","C","D"},0),1,2,3,4),"") -> 3 | F7: =IFERROR(CHOOSE(MATCH('📝 Questionnaire'!D16,{"A","B","C","D"},0),1,2,3,4),"") -> 2 | G7: =IFERROR(CHOOSE(MATCH('📝 Questionnaire'!D22,{"A","B","C","D"},0),1,2,3,4),"") -> 3 | H7: =IFERROR(ROUND(AVERAGE(E7:G7),1),"") -> 2.7 | I7: =IF(H7="","",IF(H7<1.5,"1 – Amateur",IF(H7<2.5,"2 – Collaborator",IF(H7<3.5,"3 – Enabler","4 – Driving Force")))) -> 3 – Enabler
A8: 2 | B8: 1.2 | C8: Strategic Risk & Failure Prevention | D8: Root Cause Analysis & Risk Assessment | E8: =IFERROR(CHOOSE(MATCH('📝 Questionnaire'!D28,{"A","B","C","D"},0),1,2,3,4),"") -> 4 | F8: =IFERROR(CHOOSE(MATCH('📝 Questionnaire'!D34,{"A","B","C","D"},0),1,2,3,4),"") -> 2 | G8: =IFERROR(CHOOSE(MATCH('📝 Questionnaire'!D40,{"A","B","C","D"},0),1,2,3,4),"") -> 4 | H8: =IFERROR(ROUND(AVERAGE(E8:G8),1),"") -> 3.3 | I8: =IF(H8="","",IF(H8<1.5,"1 – Amateur",IF(H8<2.5,"2 – Collaborator",IF(H8<3.5,"3 – Enabler","4 – Driving Force")))) -> 3 – Enabler
A9: 3 | B9: 1.3 | C9: Integrated Risk & Impact Analysis | D9: Root Cause Analysis & Risk Assessment | E9: =IFERROR(CHOOSE(MATCH('📝 Questionnaire'!D46,{"A","B","C","D"},0),1,2,3,4),"") -> 1 | F9: =IFERROR(CHOOSE(MATCH('📝 Questionnaire'!D52,{"A","B","C","D"},0),1,2,3,4),"") -> 2 | G9: =IFERROR(CHOOSE(MATCH('📝 Questionnaire'!D58,{"A","B","C","D"},0),1,2,3,4),"") -> 2 | H9: =IFERROR(ROUND(AVERAGE(E9:G9),1),"") -> 1.7 | I9: =IF(H9="","",IF(H9<1.5,"1 – Amateur",IF(H9<2.5,"2 – Collaborator",IF(H9<3.5,"3 – Enabler","4 – Driving Force")))) -> 2 – Collaborator
A10: 4 | B10: 1.4 | C10: Proactive Risk & Operational Resilience | D10: Root Cause Analysis & Risk Assessment | E10: =IFERROR(CHOOSE(MATCH('📝 Questionnaire'!D64,{"A","B","C","D"},0),1,2,3,4),"") -> 1 | F10: =IFERROR(CHOOSE(MATCH('📝 Questionnaire'!D70,{"A","B","C","D"},0),1,2,3,4),"") -> 4 | G10: =IFERROR(CHOOSE(MATCH('📝 Questionnaire'!D76,{"A","B","C","D"},0),1,2,3,4),"") -> 1 | H10: =IFERROR(ROUND(AVERAGE(E10:G10),1),"") -> 2 | I10: =IF(H10="","",IF(H10<1.5,"1 – Amateur",IF(H10<2.5,"2 – Collaborator",IF(H10<3.5,"3 – Enabler","4 – Driving Force")))) -> 2 – Collaborator
A11: 5 | B11: 1.5 | C11: Executive Risk Strategy & Innovation | D11: Root Cause Analysis & Risk Assessment | E11: =IFERROR(CHOOSE(MATCH('📝 Questionnaire'!D82,{"A","B","C","D"},0),1,2,3,4),"") -> 3 | F11: =IFERROR(CHOOSE(MATCH('📝 Questionnaire'!D88,{"A","B","C","D"},0),1,2,3,4),"") -> 3 | G11: =IFERROR(CHOOSE(MATCH('📝 Questionnaire'!D94,{"A","B","C","D"},0),1,2,3,4),"") -> 4 | H11: =IFERROR(ROUND(AVERAGE(E11:G11),1),"") -> 3.3 | I11: =IF(H11="","",IF(H11<1.5,"1 – Amateur",IF(H11<2.5,"2 – Collaborator",IF(H11<3.5,"3 – Enabler","4 – Driving Force")))) -> 3 – Enabler
A13: 2. Stakeholder & Contract Management
A14: 6 | B14: 2.1 | C14: Stakeholder & Contract Governance | D14: Stakeholder & Contract Management | E14: =IFERROR(CHOOSE(MATCH('📝 Questionnaire'!D103,{"A","B","C","D"},0),1,2,3,4),"") | F14: =IFERROR(CHOOSE(MATCH('📝 Questionnaire'!D109,{"A","B","C","D"},0),1,2,3,4),"") | G14: =IFERROR(CHOOSE(MATCH('📝 Questionnaire'!D115,{"A","B","C","D"},0),1,2,3,4),"") | H14: =IFERROR(ROUND(AVERAGE(E14:G14),1),"") | I14: =IF(H14="","",IF(H14<1.5,"1 – Amateur",IF(H14<2.5,"2 – Collaborator",IF(H14<3.5,"3 – Enabler","4 – Driving Force"))))
A15: 7 | B15: 2.2 | C15: Stakeholder & Contract Negotiation | D15: Stakeholder & Contract Management | E15: =IFERROR(CHOOSE(MATCH('📝 Questionnaire'!D121,{"A","B","C","D"},0),1,2,3,4),"") | F15: =IFERROR(CHOOSE(MATCH('📝 Questionnaire'!D127,{"A","B","C","D"},0),1,2,3,4),"") | G15: =IFERROR(CHOOSE(MATCH('📝 Questionnaire'!D133,{"A","B","C","D"},0),1,2,3,4),"") | H15: =IFERROR(ROUND(AVERAGE(E15:G15),1),"") | I15: =IF(H15="","",IF(H15<1.5,"1 – Amateur",IF(H15<2.5,"2 – Collaborator",IF(H15<3.5,"3 – Enabler","4 – Driving Force"))))
A16: 8 | B16: 2.3 | C16: Stakeholder-Centric Contract Governance | D16: Stakeholder & Contract Management | E16: =IFERROR(CHOOSE(MATCH('📝 Questionnaire'!D139,{"A","B","C","D"},0),1,2,3,4),"") | F16: =IFERROR(CHOOSE(MATCH('📝 Questionnaire'!D145,{"A","B","C","D"},0),1,2,3,4),"") | G16: =IFERROR(CHOOSE(MATCH('📝 Questionnaire'!D151,{"A","B","C","D"},0),1,2,3,4),"") | H16: =IFERROR(ROUND(AVERAGE(E16:G16),1),"") | I16: =IF(H16="","",IF(H16<1.5,"1 – Amateur",IF(H16<2.5,"2 – Collaborator",IF(H16<3.5,"3 – Enabler","4 – Driving Force"))))
A17: 9 | B17: 2.4 | C17: Strategic Contract Compliance | D17: Stakeholder & Contract Management | E17: =IFERROR(CHOOSE(MATCH('📝 Questionnaire'!D157,{"A","B","C","D"},0),1,2,3,4),"") | F17: =IFERROR(CHOOSE(MATCH('📝 Questionnaire'!D163,{"A","B","C","D"},0),1,2,3,4),"") | G17: =IFERROR(CHOOSE(MATCH('📝 Questionnaire'!D169,{"A","B","C","D"},0),1,2,3,4),"") | H17: =IFERROR(ROUND(AVERAGE(E17:G17),1),"") | I17: =IF(H17="","",IF(H17<1.5,"1 – Amateur",IF(H17<2.5,"2 – Collaborator",IF(H17<3.5,"3 – Enabler","4 – Driving Force"))))
A18: 10 | B18: 2.5 | C18: Ethical Stakeholder Leadership | D18: Stakeholder & Contract Management | E18: =IFERROR(CHOOSE(MATCH('📝 Questionnaire'!D175,{"A","B","C","D"},0),1,2,3,4),"") | F18: =IFERROR(CHOOSE(MATCH('📝 Questionnaire'!D181,{"A","B","C","D"},0),1,2,3,4),"") | G18: =IFERROR(CHOOSE(MATCH('📝 Questionnaire'!D187,{"A","B","C","D"},0),1,2,3,4),"") | H18: =IFERROR(ROUND(AVERAGE(E18:G18),1),"") | I18: =IF(H18="","",IF(H18<1.5,"1 – Amateur",IF(H18<2.5,"2 – Collaborator",IF(H18<3.5,"3 – Enabler","4 – Driving Force"))))
A19: 11 | B19: 2.6 | C19: Stakeholder & Contract Performance | D19: Stakeholder & Contract Management | E19: =IFERROR(CHOOSE(MATCH('📝 Questionnaire'!D193,{"A","B","C","D"},0),1,2,3,4),"") | F19: =IFERROR(CHOOSE(MATCH('📝 Questionnaire'!D199,{"A","B","C","D"},0),1,2,3,4),"") | G19: =IFERROR(CHOOSE(MATCH('📝 Questionnaire'!D205,{"A","B","C","D"},0),1,2,3,4),"") | H19: =IFERROR(ROUND(AVERAGE(E19:G19),1),"") | I19: =IF(H19="","",IF(H19<1.5,"1 – Amateur",IF(H19<2.5,"2 – Collaborator",IF(H19<3.5,"3 – Enabler","4 – Driving Force"))))
A21: 3. Project Planning & Execution
A22: 12 | B22: 3.1 | C22: Enterprise Project Strategy & Execution | D22: Project Planning & Execution | E22: =IFERROR(CHOOSE(MATCH('📝 Questionnaire'!D214,{"A","B","C","D"},0),1,2,3,4),"") | F22: =IFERROR(CHOOSE(MATCH('📝 Questionnaire'!D220,{"A","B","C","D"},0),1,2,3,4),"") | G22: =IFERROR(CHOOSE(MATCH('📝 Questionnaire'!D226,{"A","B","C","D"},0),1,2,3,4),"") | H22: =IFERROR(ROUND(AVERAGE(E22:G22),1),"") | I22: =IF(H22="","",IF(H22<1.5,"1 – Amateur",IF(H22<2.5,"2 – Collaborator",IF(H22<3.5,"3 – Enabler","4 – Driving Force"))))
A23: 13 | B23: 3.2 | C23: Strategic Project Planning & Optimization | D23: Project Planning & Execution | E23: =IFERROR(CHOOSE(MATCH('📝 Questionnaire'!D232,{"A","B","C","D"},0),1,2,3,4),"") | F23: =IFERROR(CHOOSE(MATCH('📝 Questionnaire'!D238,{"A","B","C","D"},0),1,2,3,4),"") | G23: =IFERROR(CHOOSE(MATCH('📝 Questionnaire'!D244,{"A","B","C","D"},0),1,2,3,4),"") | H23: =IFERROR(ROUND(AVERAGE(E23:G23),1),"") | I23: =IF(H23="","",IF(H23<1.5,"1 – Amateur",IF(H23<2.5,"2 – Collaborator",IF(H23<3.5,"3 – Enabler","4 – Driving Force"))))
A24: 14 | B24: 3.3 | C24: Project Governance & Compliance | D24: Project Planning & Execution | E24: =IFERROR(CHOOSE(MATCH('📝 Questionnaire'!D250,{"A","B","C","D"},0),1,2,3,4),"") | F24: =IFERROR(CHOOSE(MATCH('📝 Questionnaire'!D256,{"A","B","C","D"},0),1,2,3,4),"") | G24: =IFERROR(CHOOSE(MATCH('📝 Questionnaire'!D262,{"A","B","C","D"},0),1,2,3,4),"") | H24: =IFERROR(ROUND(AVERAGE(E24:G24),1),"") | I24: =IF(H24="","",IF(H24<1.5,"1 – Amateur",IF(H24<2.5,"2 – Collaborator",IF(H24<3.5,"3 – Enabler","4 – Driving Force"))))
A25: 15 | B25: 3.4 | C25: Project Monitoring & Refinement | D25: Project Planning & Execution | E25: =IFERROR(CHOOSE(MATCH('📝 Questionnaire'!D268,{"A","B","C","D"},0),1,2,3,4),"") | F25: =IFERROR(CHOOSE(MATCH('📝 Questionnaire'!D274,{"A","B","C","D"},0),1,2,3,4),"") | G25: =IFERROR(CHOOSE(MATCH('📝 Questionnaire'!D280,{"A","B","C","D"},0),1,2,3,4),"") | H25: =IFERROR(ROUND(AVERAGE(E25:G25),1),"") | I25: =IF(H25="","",IF(H25<1.5,"1 – Amateur",IF(H25<2.5,"2 – Collaborator",IF(H25<3.5,"3 – Enabler","4 – Driving Force"))))
A26: 16 | B26: 3.5 | C26: Cross-Functional Project Leadership | D26: Project Planning & Execution | E26: =IFERROR(CHOOSE(MATCH('📝 Questionnaire'!D286,{"A","B","C","D"},0),1,2,3,4),"") | F26: =IFERROR(CHOOSE(MATCH('📝 Questionnaire'!D292,{"A","B","C","D"},0),1,2,3,4),"") | G26: =IFERROR(CHOOSE(MATCH('📝 Questionnaire'!D298,{"A","B","C","D"},0),1,2,3,4),"") | H26: =IFERROR(ROUND(AVERAGE(E26:G26),1),"") | I26: =IF(H26="","",IF(H26<1.5,"1 – Amateur",IF(H26<2.5,"2 – Collaborator",IF(H26<3.5,"3 – Enabler","4 – Driving Force"))))
A28: 4. Proposal Development & Internal Coordination
A29: 17 | B29: 4.1 | C29: Proposal Development & Governance | D29: Proposal Development & Internal Coordination | E29: =IFERROR(CHOOSE(MATCH('📝 Questionnaire'!D307,{"A","B","C","D"},0),1,2,3,4),"") | F29: =IFERROR(CHOOSE(MATCH('📝 Questionnaire'!D313,{"A","B","C","D"},0),1,2,3,4),"") | G29: =IFERROR(CHOOSE(MATCH('📝 Questionnaire'!D319,{"A","B","C","D"},0),1,2,3,4),"") | H29: =IFERROR(ROUND(AVERAGE(E29:G29),1),"") | I29: =IF(H29="","",IF(H29<1.5,"1 – Amateur",IF(H29<2.5,"2 – Collaborator",IF(H29<3.5,"3 – Enabler","4 – Driving Force"))))
A30: 18 | B30: 4.2 | C30: Proposal Alignment & Optimization | D30: Proposal Development & Internal Coordination | E30: =IFERROR(CHOOSE(MATCH('📝 Questionnaire'!D325,{"A","B","C","D"},0),1,2,3,4),"") | F30: =IFERROR(CHOOSE(MATCH('📝 Questionnaire'!D331,{"A","B","C","D"},0),1,2,3,4),"") | G30: =IFERROR(CHOOSE(MATCH('📝 Questionnaire'!D337,{"A","B","C","D"},0),1,2,3,4),"") | H30: =IFERROR(ROUND(AVERAGE(E30:G30),1),"") | I30: =IF(H30="","",IF(H30<1.5,"1 – Amateur",IF(H30<2.5,"2 – Collaborator",IF(H30<3.5,"3 – Enabler","4 – Driving Force"))))
A31: 19 | B31: 4.3 | C31: Communication & Negotiation Excellence | D31: Proposal Development & Internal Coordination | E31: =IFERROR(CHOOSE(MATCH('📝 Questionnaire'!D343,{"A","B","C","D"},0),1,2,3,4),"") | F31: =IFERROR(CHOOSE(MATCH('📝 Questionnaire'!D349,{"A","B","C","D"},0),1,2,3,4),"") | G31: =IFERROR(CHOOSE(MATCH('📝 Questionnaire'!D355,{"A","B","C","D"},0),1,2,3,4),"") | H31: =IFERROR(ROUND(AVERAGE(E31:G31),1),"") | I31: =IF(H31="","",IF(H31<1.5,"1 – Amateur",IF(H31<2.5,"2 – Collaborator",IF(H31<3.5,"3 – Enabler","4 – Driving Force"))))
A32: 20 | B32: 4.4 | C32: Proposal Governance Strategy | D32: Proposal Development & Internal Coordination | E32: =IFERROR(CHOOSE(MATCH('📝 Questionnaire'!D361,{"A","B","C","D"},0),1,2,3,4),"") | F32: =IFERROR(CHOOSE(MATCH('📝 Questionnaire'!D367,{"A","B","C","D"},0),1,2,3,4),"") | G32: =IFERROR(CHOOSE(MATCH('📝 Questionnaire'!D373,{"A","B","C","D"},0),1,2,3,4),"") | H32: =IFERROR(ROUND(AVERAGE(E32:G32),1),"") | I32: =IF(H32="","",IF(H32<1.5,"1 – Amateur",IF(H32<2.5,"2 – Collaborator",IF(H32<3.5,"3 – Enabler","4 – Driving Force"))))
A33: 21 | B33: 4.5 | C33: Proposal Excellence & Impact | D33: Proposal Development & Internal Coordination | E33: =IFERROR(CHOOSE(MATCH('📝 Questionnaire'!D379,{"A","B","C","D"},0),1,2,3,4),"") | F33: =IFERROR(CHOOSE(MATCH('📝 Questionnaire'!D385,{"A","B","C","D"},0),1,2,3,4),"") | G33: =IFERROR(CHOOSE(MATCH('📝 Questionnaire'!D391,{"A","B","C","D"},0),1,2,3,4),"") | H33: =IFERROR(ROUND(AVERAGE(E33:G33),1),"") | I33: =IF(H33="","",IF(H33<1.5,"1 – Amateur",IF(H33<2.5,"2 – Collaborator",IF(H33<3.5,"3 – Enabler","4 – Driving Force"))))
A35: 5. Resource Management & Budget Control
A36: 22 | B36: 5.1 | C36: Enterprise Budgeting & Resource Optimization | D36: Resource Management & Budget Control | E36: =IFERROR(CHOOSE(MATCH('📝 Questionnaire'!D400,{"A","B","C","D"},0),1,2,3,4),"") | F36: =IFERROR(CHOOSE(MATCH('📝 Questionnaire'!D406,{"A","B","C","D"},0),1,2,3,4),"") | G36: =IFERROR(CHOOSE(MATCH('📝 Questionnaire'!D412,{"A","B","C","D"},0),1,2,3,4),"") | H36: =IFERROR(ROUND(AVERAGE(E36:G36),1),"") | I36: =IF(H36="","",IF(H36<1.5,"1 – Amateur",IF(H36<2.5,"2 – Collaborator",IF(H36<3.5,"3 – Enabler","4 – Driving Force"))))
A37: 23 | B37: 5.2 | C37: Financial Compliance & Resource Governance | D37: Resource Management & Budget Control | E37: =IFERROR(CHOOSE(MATCH('📝 Questionnaire'!D418,{"A","B","C","D"},0),1,2,3,4),"") | F37: =IFERROR(CHOOSE(MATCH('📝 Questionnaire'!D424,{"A","B","C","D"},0),1,2,3,4),"") | G37: =IFERROR(CHOOSE(MATCH('📝 Questionnaire'!D430,{"A","B","C","D"},0),1,2,3,4),"") | H37: =IFERROR(ROUND(AVERAGE(E37:G37),1),"") | I37: =IF(H37="","",IF(H37<1.5,"1 – Amateur",IF(H37<2.5,"2 – Collaborator",IF(H37<3.5,"3 – Enabler","4 – Driving Force"))))
A38: 24 | B38: 5.3 | C38: Financial Automation & Optimization | D38: Resource Management & Budget Control | E38: =IFERROR(CHOOSE(MATCH('📝 Questionnaire'!D436,{"A","B","C","D"},0),1,2,3,4),"") | F38: =IFERROR(CHOOSE(MATCH('📝 Questionnaire'!D442,{"A","B","C","D"},0),1,2,3,4),"") | G38: =IFERROR(CHOOSE(MATCH('📝 Questionnaire'!D448,{"A","B","C","D"},0),1,2,3,4),"") | H38: =IFERROR(ROUND(AVERAGE(E38:G38),1),"") | I38: =IF(H38="","",IF(H38<1.5,"1 – Amateur",IF(H38<2.5,"2 – Collaborator",IF(H38<3.5,"3 – Enabler","4 – Driving Force"))))
A39: 25 | B39: 5.4 | C39: Cost Efficiency & Waste Reduction | D39: Resource Management & Budget Control | E39: =IFERROR(CHOOSE(MATCH('📝 Questionnaire'!D454,{"A","B","C","D"},0),1,2,3,4),"") | F39: =IFERROR(CHOOSE(MATCH('📝 Questionnaire'!D460,{"A","B","C","D"},0),1,2,3,4),"") | G39: =IFERROR(CHOOSE(MATCH('📝 Questionnaire'!D466,{"A","B","C","D"},0),1,2,3,4),"") | H39: =IFERROR(ROUND(AVERAGE(E39:G39),1),"") | I39: =IF(H39="","",IF(H39<1.5,"1 – Amateur",IF(H39<2.5,"2 – Collaborator",IF(H39<3.5,"3 – Enabler","4 – Driving Force"))))
A40: 26 | B40: 5.5 | C40: Budget Variance Analysis & Optimization | D40: Resource Management & Budget Control | E40: =IFERROR(CHOOSE(MATCH('📝 Questionnaire'!D472,{"A","B","C","D"},0),1,2,3,4),"") | F40: =IFERROR(CHOOSE(MATCH('📝 Questionnaire'!D478,{"A","B","C","D"},0),1,2,3,4),"") | G40: =IFERROR(CHOOSE(MATCH('📝 Questionnaire'!D484,{"A","B","C","D"},0),1,2,3,4),"") | H40: =IFERROR(ROUND(AVERAGE(E40:G40),1),"") | I40: =IF(H40="","",IF(H40<1.5,"1 – Amateur",IF(H40<2.5,"2 – Collaborator",IF(H40<3.5,"3 – Enabler","4 – Driving Force"))))
A41: 27 | B41: 5.6 | C41: Financial Governance & Resource Optimization | D41: Resource Management & Budget Control | E41: =IFERROR(CHOOSE(MATCH('📝 Questionnaire'!D490,{"A","B","C","D"},0),1,2,3,4),"") | F41: =IFERROR(CHOOSE(MATCH('📝 Questionnaire'!D496,{"A","B","C","D"},0),1,2,3,4),"") | G41: =IFERROR(CHOOSE(MATCH('📝 Questionnaire'!D502,{"A","B","C","D"},0),1,2,3,4),"") | H41: =IFERROR(ROUND(AVERAGE(E41:G41),1),"") | I41: =IF(H41="","",IF(H41<1.5,"1 – Amateur",IF(H41<2.5,"2 – Collaborator",IF(H41<3.5,"3 – Enabler","4 – Driving Force"))))
A43: 6. Digital PM & Technology Innovation
A44: 28 | B44: 6.1 | C44: PM System Optimization | D44: Digital PM & Technology Innovation | E44: =IFERROR(CHOOSE(MATCH('📝 Questionnaire'!D511,{"A","B","C","D"},0),1,2,3,4),"") | F44: =IFERROR(CHOOSE(MATCH('📝 Questionnaire'!D517,{"A","B","C","D"},0),1,2,3,4),"") | G44: =IFERROR(CHOOSE(MATCH('📝 Questionnaire'!D523,{"A","B","C","D"},0),1,2,3,4),"") | H44: =IFERROR(ROUND(AVERAGE(E44:G44),1),"") | I44: =IF(H44="","",IF(H44<1.5,"1 – Amateur",IF(H44<2.5,"2 – Collaborator",IF(H44<3.5,"3 – Enabler","4 – Driving Force"))))
A45: 29 | B45: 6.2 | C45: AI-Driven Digital Efficiency & Automation | D45: Digital PM & Technology Innovation | E45: =IFERROR(CHOOSE(MATCH('📝 Questionnaire'!D529,{"A","B","C","D"},0),1,2,3,4),"") | F45: =IFERROR(CHOOSE(MATCH('📝 Questionnaire'!D535,{"A","B","C","D"},0),1,2,3,4),"") | G45: =IFERROR(CHOOSE(MATCH('📝 Questionnaire'!D541,{"A","B","C","D"},0),1,2,3,4),"") | H45: =IFERROR(ROUND(AVERAGE(E45:G45),1),"") | I45: =IF(H45="","",IF(H45<1.5,"1 – Amateur",IF(H45<2.5,"2 – Collaborator",IF(H45<3.5,"3 – Enabler","4 – Driving Force"))))
A46: 30 | B46: 6.3 | C46: AI-Driven ERP Transformation | D46: Digital PM & Technology Innovation | E46: =IFERROR(CHOOSE(MATCH('📝 Questionnaire'!D547,{"A","B","C","D"},0),1,2,3,4),"") | F46: =IFERROR(CHOOSE(MATCH('📝 Questionnaire'!D553,{"A","B","C","D"},0),1,2,3,4),"") | G46: =IFERROR(CHOOSE(MATCH('📝 Questionnaire'!D559,{"A","B","C","D"},0),1,2,3,4),"") | H46: =IFERROR(ROUND(AVERAGE(E46:G46),1),"") | I46: =IF(H46="","",IF(H46<1.5,"1 – Amateur",IF(H46<2.5,"2 – Collaborator",IF(H46<3.5,"3 – Enabler","4 – Driving Force"))))
A47: 31 | B47: 6.4 | C47: IT Enablement & Digital Innovation | D47: Digital PM & Technology Innovation | E47: =IFERROR(CHOOSE(MATCH('📝 Questionnaire'!D565,{"A","B","C","D"},0),1,2,3,4),"") | F47: =IFERROR(CHOOSE(MATCH('📝 Questionnaire'!D571,{"A","B","C","D"},0),1,2,3,4),"") | G47: =IFERROR(CHOOSE(MATCH('📝 Questionnaire'!D577,{"A","B","C","D"},0),1,2,3,4),"") | H47: =IFERROR(ROUND(AVERAGE(E47:G47),1),"") | I47: =IF(H47="","",IF(H47<1.5,"1 – Amateur",IF(H47<2.5,"2 – Collaborator",IF(H47<3.5,"3 – Enabler","4 – Driving Force"))))
...
