Workbook

Sheet 📋 Instructions
A1: PROJECT MANAGEMENT COMPETENCY ASSESSMENT FRAMEWORK
A2: Technical Competency Assessment Tool | Line Manager & Self-Evaluation
A4: 📌 HOW TO USE THIS TOOL
B5: Step 1: Enter Employee Details
B6: Go to '👤 Employee Assessment'. Enter Name, Position, Division, Department, Date.
B8: Step 2: Employee Self-Evaluation (Column K)
B9: The EMPLOYEE rates themselves honestly on each sub-competency (1–5). This is done BEFORE the Line Manager rates.
B11: Step 3: Line Manager Rating (Column L)
B12: The LINE MANAGER independently rates the same sub-competencies (1–5) based on observed behaviour.
B14: Step 4: Review Auto-Calculated Results
B15: Gap Analysis is based on LM rating only. The tool shows: Required Level, LM Rating, Gap, and Status per sub-competency.
B17: Step 5: Compare Self vs LM Rating
B18: Column M shows the difference (Self − LM). Positive = employee overestimates; Negative = employee underestimates.
B20: Step 6: Competency Gap at a Glance
B21: The Summary section shows a TRAFFIC LIGHT score: 🟢 Strong 🟡 Developing 🔴 Needs Focus.
... B24: Go to '📊 PM Family Summary' to view all employees. '📈 Dashboard' shows division and designation analytics.
A27: 📊 COMPETENCY SCALE — 5 STAGES
B28: Rating | C28: Stage | D28: Description in Plain Language | E28: Color
B29: 1 | C29: Amateur | D29: Just starting. Needs step-by-step supervision on almost every task. | E29: ◼◼◼
B30: 2 | C30: Collaborator | D30: Building skills. Can contribute but still needs support from others. | E30: ◼◼◼
B31: 3 | C31: Enabler | D31: Competent and independent. Handles routine tasks without supervision. | E31: ◼◼◼
B32: 4 | C32: Driving Force | D32: Advanced. Leads others, improves practices, goes beyond the basics. | E32: ◼◼◼
B33: 5 | C33: Visionary | D33: Expert. Shapes strategy, mentors teams, drives company-wide impact. | E33: ◼◼◼
A37: 🚦 SKILL GAP SCORE — EASY GUIDE FOR LEADERSHIP
B38: Score | C38: What it means | D38: Traffic Light | E38: Board-level message
B39: 0 – 10 | C39: Employee meets all or nearly all requirements | D39: 🟢 Strong | E39: No action needed — maintain and recognise
B40: 11 – 30 | C40: Some gaps exist — moderate development needed | D40: 🟡 Developing | E40: Targeted development plan recommended
B41: 31 – 60 | C41: Significant gaps across multiple competencies | D41: 🟠 Needs Focus | E41: Structured development plan required
B42: > 60 | C42: Critical gaps — employee significantly below requirements | D42: 🔴 Critical | E42: Urgent intervention and close monitoring needed
A43: ① Competency Gap = Sum of (Required Level − LM Rating) for all sub-competencies. Higher = more development needed. ② % Gap = Total Gap ÷ Max Possible × 100. 0% = fully meets requirements. ③ Self vs LM Difference = Employee's own rating minus LM rating. Positive = employee over-rates themselves.

Sheet 👤 Employee Assessment
A1: PROJECT MANAGEMENT — COMPETENCY ASSESSMENT SHEET
A2: Project Management Job Family | Step 1: Employee Self-Rates → Step 2: Line Manager Rates | Gap analysis based on LM rating
B4: Employee Name: | I4: Date: | L4: Assessor (Line Manager):
B5: Position: | D5: Chief | F5: Division: | I5: Department: | L5: Assessment Period:
B6: Employee ID: | F6: Grade / Band: | I6: Years in Role:
B7: # | C7: Sub-Competency | D7: IC/DM Req. | E7: Mgr Req. | F7: Head Req. | G7: Chief Req. | H7: Required Competency Level (Auto) | I7: ① Employee Self-Rating (1–5) | J7: ② Line Manager Rating (1–5) ★ | K7: Skill Gap (Req − LM) | L7: Self vs LM (Self − LM) | M7: LM Competency Level Stage | N7: Status
I8: Employee fills first ↑ | J8: LM fills second ↑
B9: 1. ROOT CAUSE ANALYSIS & RISK ASSESSMENT
B10: 1.1 | C10: Root Cause & Risk Management Mastery | D10: 3 | E10: 2 | F10: 4 | G10: 5 | H10: =IF($D$5="","",IF($D$5="In-charge / DM",D10,IF($D$5="Manager",E10,IF($D$5="Head",F10,IF($D$5="Chief",G10,""))))) -> 5 | I10: 3 | J10: 4 | K10: =IF(J10="","",IF(H10="","",H10-J10)) -> 1 | L10: =IF(I10="","",IF(J10="","",I10-J10)) -> -1 | M10: =IF(J10="","—",IF(J10<1.5,"Amateur",IF(J10<2.5,"Collaborator",IF(J10<3.5,"Enabler",IF(J10<4.5,"Driving Force","Visionary"))))) -> Driving Force | N10: =IF(J10="","—",IF(K10>0,"▼ Below Required",IF(K10=0,"✔ At Target","▲ Exceeds Target"))) -> ▼ Below Required
B11: 1.2 | C11: Strategic Risk & Failure Prevention | D11: 3 | E11: 2 | F11: 4 | G11: 5 | H11: =IF($D$5="","",IF($D$5="In-charge / DM",D11,IF($D$5="Manager",E11,IF($D$5="Head",F11,IF($D$5="Chief",G11,""))))) -> 5 | I11: 4 | J11: 3 | K11: =IF(J11="","",IF(H11="","",H11-J11)) -> 2 | L11: =IF(I11="","",IF(J11="","",I11-J11)) -> 1 | M11: =IF(J11="","—",IF(J11<1.5,"Amateur",IF(J11<2.5,"Collaborator",IF(J11<3.5,"Enabler",IF(J11<4.5,"Driving Force","Visionary"))))) -> Enabler | N11: =IF(J11="","—",IF(K11>0,"▼ Below Required",IF(K11=0,"✔ At Target","▲ Exceeds Target"))) -> ▼ Below Required
B12: 1.3 | C12: Integrated Risk & Impact Analysis | D12: 3 | E12: 2 | F12: 4 | G12: 5 | H12: =IF($D$5="","",IF($D$5="In-charge / DM",D12,IF($D$5="Manager",E12,IF($D$5="Head",F12,IF($D$5="Chief",G12,""))))) -> 5 | I12: 4 | J12: 3 | K12: =IF(J12="","",IF(H12="","",H12-J12)) -> 2 | L12: =IF(I12="","",IF(J12="","",I12-J12)) -> 1 | M12: =IF(J12="","—",IF(J12<1.5,"Amateur",IF(J12<2.5,"Collaborator",IF(J12<3.5,"Enabler",IF(J12<4.5,"Driving Force","Visionary"))))) -> Enabler | N12: =IF(J12="","—",IF(K12>0,"▼ Below Required",IF(K12=0,"✔ At Target","▲ Exceeds Target"))) -> ▼ Below Required
B13: 1.4 | C13: Proactive Risk & Operational Resilience | D13: 3 | E13: 2 | F13: 5 | G13: 5 | H13: =IF($D$5="","",IF($D$5="In-charge / DM",D13,IF($D$5="Manager",E13,IF($D$5="Head",F13,IF($D$5="Chief",G13,""))))) -> 5 | I13: 4 | J13: 3 | K13: =IF(J13="","",IF(H13="","",H13-J13)) -> 2 | L13: =IF(I13="","",IF(J13="","",I13-J13)) -> 1 | M13: =IF(J13="","—",IF(J13<1.5,"Amateur",IF(J13<2.5,"Collaborator",IF(J13<3.5,"Enabler",IF(J13<4.5,"Driving Force","Visionary"))))) -> Enabler | N13: =IF(J13="","—",IF(K13>0,"▼ Below Required",IF(K13=0,"✔ At Target","▲ Exceeds Target"))) -> ▼ Below Required
B14: 1.5 | C14: Executive Risk Strategy & Innovation | D14: 1 | E14: 4 | F14: 4 | G14: 5 | H14: =IF($D$5="","",IF($D$5="In-charge / DM",D14,IF($D$5="Manager",E14,IF($D$5="Head",F14,IF($D$5="Chief",G14,""))))) -> 5 | I14: 4 | J14: 3 | K14: =IF(J14="","",IF(H14="","",H14-J14)) -> 2 | L14: =IF(I14="","",IF(J14="","",I14-J14)) -> 1 | M14: =IF(J14="","—",IF(J14<1.5,"Amateur",IF(J14<2.5,"Collaborator",IF(J14<3.5,"Enabler",IF(J14<4.5,"Driving Force","Visionary"))))) -> Enabler | N14: =IF(J14="","—",IF(K14>0,"▼ Below Required",IF(K14=0,"✔ At Target","▲ Exceeds Target"))) -> ▼ Below Required
B15: ∑ Root Cause Analysis & Risk Assessment | H15: Req → | I15: =IFERROR(AVERAGE(I10:I14),"") -> 3.8 | J15: =IFERROR(AVERAGE(J10:J14),"") -> 3.2 | K15: =IFERROR(SUM(K10:K14),"") -> 9 | L15: =IFERROR(AVERAGE(I10:I14)-AVERAGE(J10:J14),"") -> 0.6 | M15: LM Stage | N15: ← Gap Total
B17: 2. STAKEHOLDER & CONTRACT MANAGEMENT
B18: 2.1 | C18: Strategic Stakeholder & Contract Governance | D18: 3 | E18: 2 | F18: 4 | G18: 5 | H18: =IF($D$5="","",IF($D$5="In-charge / DM",D18,IF($D$5="Manager",E18,IF($D$5="Head",F18,IF($D$5="Chief",G18,""))))) -> 5 | I18: 3 | J18: 3 | K18: =IF(J18="","",IF(H18="","",H18-J18)) -> 2 | L18: =IF(I18="","",IF(J18="","",I18-J18)) -> 0 | M18: =IF(J18="","—",IF(J18<1.5,"Amateur",IF(J18<2.5,"Collaborator",IF(J18<3.5,"Enabler",IF(J18<4.5,"Driving Force","Visionary"))))) -> Enabler | N18: =IF(J18="","—",IF(K18>0,"▼ Below Required",IF(K18=0,"✔ At Target","▲ Exceeds Target"))) -> ▼ Below Required
B19: 2.2 | C19: Visionary Stakeholder & Contract Negotiation | D19: 2 | E19: 4 | F19: 4 | G19: 5 | H19: =IF($D$5="","",IF($D$5="In-charge / DM",D19,IF($D$5="Manager",E19,IF($D$5="Head",F19,IF($D$5="Chief",G19,""))))) -> 5 | I19: 4 | J19: 3 | K19: =IF(J19="","",IF(H19="","",H19-J19)) -> 2 | L19: =IF(I19="","",IF(J19="","",I19-J19)) -> 1 | M19: =IF(J19="","—",IF(J19<1.5,"Amateur",IF(J19<2.5,"Collaborator",IF(J19<3.5,"Enabler",IF(J19<4.5,"Driving Force","Visionary"))))) -> Enabler | N19: =IF(J19="","—",IF(K19>0,"▼ Below Required",IF(K19=0,"✔ At Target","▲ Exceeds Target"))) -> ▼ Below Required
B20: 2.3 | C20: Stakeholder-Centric Contract Governance | D20: 3 | E20: 2 | F20: 2 | G20: 5 | H20: =IF($D$5="","",IF($D$5="In-charge / DM",D20,IF($D$5="Manager",E20,IF($D$5="Head",F20,IF($D$5="Chief",G20,""))))) -> 5 | I20: 2 | J20: 4 | K20: =IF(J20="","",IF(H20="","",H20-J20)) -> 1 | L20: =IF(I20="","",IF(J20="","",I20-J20)) -> -2 | M20: =IF(J20="","—",IF(J20<1.5,"Amateur",IF(J20<2.5,"Collaborator",IF(J20<3.5,"Enabler",IF(J20<4.5,"Driving Force","Visionary"))))) -> Driving Force | N20: =IF(J20="","—",IF(K20>0,"▼ Below Required",IF(K20=0,"✔ At Target","▲ Exceeds Target"))) -> ▼ Below Required
B21: 2.4 | C21: Strategic Contract Compliance & Negotiation | D21: 1 | E21: 2 | F21: 4 | G21: 5 | H21: =IF($D$5="","",IF($D$5="In-charge / DM",D21,IF($D$5="Manager",E21,IF($D$5="Head",F21,IF($D$5="Chief",G21,""))))) -> 5 | I21: 4 | J21: 3 | K21: =IF(J21="","",IF(H21="","",H21-J21)) -> 2 | L21: =IF(I21="","",IF(J21="","",I21-J21)) -> 1 | M21: =IF(J21="","—",IF(J21<1.5,"Amateur",IF(J21<2.5,"Collaborator",IF(J21<3.5,"Enabler",IF(J21<4.5,"Driving Force","Visionary"))))) -> Enabler | N21: =IF(J21="","—",IF(K21>0,"▼ Below Required",IF(K21=0,"✔ At Target","▲ Exceeds Target"))) -> ▼ Below Required
B22: 2.5 | C22: Ethical Stakeholder & Contract Leadership | D22: 3 | E22: 4 | F22: 4 | G22: 4 | H22: =IF($D$5="","",IF($D$5="In-charge / DM",D22,IF($D$5="Manager",E22,IF($D$5="Head",F22,IF($D$5="Chief",G22,""))))) -> 4 | I22: 4 | J22: 3 | K22: =IF(J22="","",IF(H22="","",H22-J22)) -> 1 | L22: =IF(I22="","",IF(J22="","",I22-J22)) -> 1 | M22: =IF(J22="","—",IF(J22<1.5,"Amateur",IF(J22<2.5,"Collaborator",IF(J22<3.5,"Enabler",IF(J22<4.5,"Driving Force","Visionary"))))) -> Enabler | N22: =IF(J22="","—",IF(K22>0,"▼ Below Required",IF(K22=0,"✔ At Target","▲ Exceeds Target"))) -> ▼ Below Required
B23: 2.6 | C23: Stakeholder & Contract Performance Optimization | D23: 3 | E23: 2 | F23: 5 | G23: 5 | H23: =IF($D$5="","",IF($D$5="In-charge / DM",D23,IF($D$5="Manager",E23,IF($D$5="Head",F23,IF($D$5="Chief",G23,""))))) -> 5 | I23: 4 | J23: 3 | K23: =IF(J23="","",IF(H23="","",H23-J23)) -> 2 | L23: =IF(I23="","",IF(J23="","",I23-J23)) -> 1 | M23: =IF(J23="","—",IF(J23<1.5,"Amateur",IF(J23<2.5,"Collaborator",IF(J23<3.5,"Enabler",IF(J23<4.5,"Driving Force","Visionary"))))) -> Enabler | N23: =IF(J23="","—",IF(K23>0,"▼ Below Required",IF(K23=0,"✔ At Target","▲ Exceeds Target"))) -> ▼ Below Required
B24: ∑ Stakeholder & Contract Management | H24: Req → | I24: =IFERROR(AVERAGE(I18:I23),"") -> 3.5 | J24: =IFERROR(AVERAGE(J18:J23),"") -> 3.1666667 | K24: =IFERROR(SUM(K18:K23),"") -> 10 | L24: =IFERROR(AVERAGE(I18:I23)-AVERAGE(J18:J23),"") -> 0.33333333 | M24: LM Stage | N24: ← Gap Total
B26: 3. PROJECT PLANNING & EXECUTION
B27: 3.1 | C27: Enterprise Project Strategy & Execution | D27: 3 | E27: 2 | F27: 4 | G27: 5 | H27: =IF($D$5="","",IF($D$5="In-charge / DM",D27,IF($D$5="Manager",E27,IF($D$5="Head",F27,IF($D$5="Chief",G27,""))))) -> 5 | I27: 3 | J27: 2 | K27: =IF(J27="","",IF(H27="","",H27-J27)) -> 3 | L27: =IF(I27="","",IF(J27="","",I27-J27)) -> 1 | M27: =IF(J27="","—",IF(J27<1.5,"Amateur",IF(J27<2.5,"Collaborator",IF(J27<3.5,"Enabler",IF(J27<4.5,"Driving Force","Visionary"))))) -> Collaborator | N27: =IF(J27="","—",IF(K27>0,"▼ Below Required",IF(K27=0,"✔ At Target","▲ Exceeds Target"))) -> ▼ Below Required
B28: 3.2 | C28: Strategic Project Planning & Optimization | D28: 1 | E28: 2 | F28: 5 | G28: 5 | H28: =IF($D$5="","",IF($D$5="In-charge / DM",D28,IF($D$5="Manager",E28,IF($D$5="Head",F28,IF($D$5="Chief",G28,""))))) -> 5 | I28: 4 | J28: 3 | K28: =IF(J28="","",IF(H28="","",H28-J28)) -> 2 | L28: =IF(I28="","",IF(J28="","",I28-J28)) -> 1 | M28: =IF(J28="","—",IF(J28<1.5,"Amateur",IF(J28<2.5,"Collaborator",IF(J28<3.5,"Enabler",IF(J28<4.5,"Driving Force","Visionary"))))) -> Enabler | N28: =IF(J28="","—",IF(K28>0,"▼ Below Required",IF(K28=0,"✔ At Target","▲ Exceeds Target"))) -> ▼ Below Required
B29: 3.3 | C29: Project Governance & Compliance Integration | D29: 1 | E29: 4 | F29: 4 | G29: 5 | H29: =IF($D$5="","",IF($D$5="In-charge / DM",D29,IF($D$5="Manager",E29,IF($D$5="Head",F29,IF($D$5="Chief",G29,""))))) -> 5 | I29: 4 | J29: 3 | K29: =IF(J29="","",IF(H29="","",H29-J29)) -> 2 | L29: =IF(I29="","",IF(J29="","",I29-J29)) -> 1 | M29: =IF(J29="","—",IF(J29<1.5,"Amateur",IF(J29<2.5,"Collaborator",IF(J29<3.5,"Enabler",IF(J29<4.5,"Driving Force","Visionary"))))) -> Enabler | N29: =IF(J29="","—",IF(K29>0,"▼ Below Required",IF(K29=0,"✔ At Target","▲ Exceeds Target"))) -> ▼ Below Required
B30: 3.4 | C30: Project Monitoring & Refinement | D30: 3 | E30: 2 | F30: 4 | G30: 4 | H30: =IF($D$5="","",IF($D$5="In-charge / DM",D30,IF($D$5="Manager",E30,IF($D$5="Head",F30,IF($D$5="Chief",G30,""))))) -> 4 | I30: 4 | J30: 3 | K30: =IF(J30="","",IF(H30="","",H30-J30)) -> 1 | L30: =IF(I30="","",IF(J30="","",I30-J30)) -> 1 | M30: =IF(J30="","—",IF(J30<1.5,"Amateur",IF(J30<2.5,"Collaborator",IF(J30<3.5,"Enabler",IF(J30<4.5,"Driving Force","Visionary"))))) -> Enabler | N30: =IF(J30="","—",IF(K30>0,"▼ Below Required",IF(K30=0,"✔ At Target","▲ Exceeds Target"))) -> ▼ Below Required
B31: 3.5 | C31: Cross-Functional Project Leadership | D31: 1 | E31: 2 | F31: 5 | G31: 5 | H31: =IF($D$5="","",IF($D$5="In-charge / DM",D31,IF($D$5="Manager",E31,IF($D$5="Head",F31,IF($D$5="Chief",G31,""))))) -> 5 | I31: 3 | J31: 3 | K31: =IF(J31="","",IF(H31="","",H31-J31)) -> 2 | L31: =IF(I31="","",IF(J31="","",I31-J31)) -> 0 | M31: =IF(J31="","—",IF(J31<1.5,"Amateur",IF(J31<2.5,"Collaborator",IF(J31<3.5,"Enabler",IF(J31<4.5,"Driving Force","Visionary"))))) -> Enabler | N31: =IF(J31="","—",IF(K31>0,"▼ Below Required",IF(K31=0,"✔ At Target","▲ Exceeds Target"))) -> ▼ Below Required
B32: ∑ Project Planning & Execution | H32: Req → | I32: =IFERROR(AVERAGE(I27:I31),"") -> 3.6 | J32: =IFERROR(AVERAGE(J27:J31),"") -> 2.8 | K32: =IFERROR(SUM(K27:K31),"") -> 10 | L32: =IFERROR(AVERAGE(I27:I31)-AVERAGE(J27:J31),"") -> 0.8 | M32: LM Stage | N32: ← Gap Total
B34: 4. PROPOSAL DEVELOPMENT & INTERNAL COORDINATION
B35: 4.1 | C35: Proposal Development & Governance | D35: 1 | E35: 2 | F35: 4 | G35: 5 | H35: =IF($D$5="","",IF($D$5="In-charge / DM",D35,IF($D$5="Manager",E35,IF($D$5="Head",F35,IF($D$5="Chief",G35,""))))) -> 5 | I35: 3 | J35: 4 | K35: =IF(J35="","",IF(H35="","",H35-J35)) -> 1 | L35: =IF(I35="","",IF(J35="","",I35-J35)) -> -1 | M35: =IF(J35="","—",IF(J35<1.5,"Amateur",IF(J35<2.5,"Collaborator",IF(J35<3.5,"Enabler",IF(J35<4.5,"Driving Force","Visionary"))))) -> Driving Force | N35: =IF(J35="","—",IF(K35>0,"▼ Below Required",IF(K35=0,"✔ At Target","▲ Exceeds Target"))) -> ▼ Below Required
B36: 4.2 | C36: Proposal Alignment & Optimization | D36: 2 | E36: 2 | F36: 4 | G36: 5 | H36: =IF($D$5="","",IF($D$5="In-charge / DM",D36,IF($D$5="Manager",E36,IF($D$5="Head",F36,IF($D$5="Chief",G36,""))))) -> 5 | I36: 3 | J36: 3 | K36: =IF(J36="","",IF(H36="","",H36-J36)) -> 2 | L36: =IF(I36="","",IF(J36="","",I36-J36)) -> 0 | M36: =IF(J36="","—",IF(J36<1.5,"Amateur",IF(J36<2.5,"Collaborator",IF(J36<3.5,"Enabler",IF(J36<4.5,"Driving Force","Visionary"))))) -> Enabler | N36: =IF(J36="","—",IF(K36>0,"▼ Below Required",IF(K36=0,"✔ At Target","▲ Exceeds Target"))) -> ▼ Below Required
B37: 4.3 | C37: Communication & Negotiation Excellence | D37: 1 | E37: 2 | F37: 2 | G37: 5 | H37: =IF($D$5="","",IF($D$5="In-charge / DM",D37,IF($D$5="Manager",E37,IF($D$5="Head",F37,IF($D$5="Chief",G37,""))))) -> 5 | I37: 3 | J37: 2 | K37: =IF(J37="","",IF(H37="","",H37-J37)) -> 3 | L37: =IF(I37="","",IF(J37="","",I37-J37)) -> 1 | M37: =IF(J37="","—",IF(J37<1.5,"Amateur",IF(J37<2.5,"Collaborator",IF(J37<3.5,"Enabler",IF(J37<4.5,"Driving Force","Visionary"))))) -> Collaborator | N37: =IF(J37="","—",IF(K37>0,"▼ Below Required",IF(K37=0,"✔ At Target","▲ Exceeds Target"))) -> ▼ Below Required
B38: 4.4 | C38: Proposal Optimization & Governance Strategy | D38: 3 | E38: 2 | F38: 4 | G38: 5 | H38: =IF($D$5="","",IF($D$5="In-charge / DM",D38,IF($D$5="Manager",E38,IF($D$5="Head",F38,IF($D$5="Chief",G38,""))))) -> 5 | I38: 3 | J38: 3 | K38: =IF(J38="","",IF(H38="","",H38-J38)) -> 2 | L38: =IF(I38="","",IF(J38="","",I38-J38)) -> 0 | M38: =IF(J38="","—",IF(J38<1.5,"Amateur",IF(J38<2.5,"Collaborator",IF(J38<3.5,"Enabler",IF(J38<4.5,"Driving Force","Visionary"))))) -> Enabler | N38: =IF(J38="","—",IF(K38>0,"▼ Below Required",IF(K38=0,"✔ At Target","▲ Exceeds Target"))) -> ▼ Below Required
B39: 4.5 | C39: Proposal Excellence & Impact | D39: 3 | E39: 4 | F39: 4 | G39: 5 | H39: =IF($D$5="","",IF($D$5="In-charge / DM",D39,IF($D$5="Manager",E39,IF($D$5="Head",F39,IF($D$5="Chief",G39,""))))) -> 5 | I39: 3 | J39: 3 | K39: =IF(J39="","",IF(H39="","",H39-J39)) -> 2 | L39: =IF(I39="","",IF(J39="","",I39-J39)) -> 0 | M39: =IF(J39="","—",IF(J39<1.5,"Amateur",IF(J39<2.5,"Collaborator",IF(J39<3.5,"Enabler",IF(J39<4.5,"Driving Force","Visionary"))))) -> Enabler | N39: =IF(J39="","—",IF(K39>0,"▼ Below Required",IF(K39=0,"✔ At Target","▲ Exceeds Target"))) -> ▼ Below Required
B40: ∑ Proposal Development & Internal Coordination | H40: Req → | I40: =IFERROR(AVERAGE(I35:I39),"") -> 3 | J40: =IFERROR(AVERAGE(J35:J39),"") -> 3 | K40: =IFERROR(SUM(K35:K39),"") -> 10 | L40: =IFERROR(AVERAGE(I35:I39)-AVERAGE(J35:J39),"") -> 0 | M40: LM Stage | N40: ← Gap Total
B42: 5. RESOURCE MANAGEMENT & BUDGET CONTROL
B43: 5.1 | C43: Enterprise Budgeting & Resource Optimization | D43: 1 | E43: 2 | F43: 4 | G43: 5 | H43: =IF($D$5="","",IF($D$5="In-charge / DM",D43,IF($D$5="Manager",E43,IF($D$5="Head",F43,IF($D$5="Chief",G43,""))))) -> 5 | I43: 4 | J43: 3 | K43: =IF(J43="","",IF(H43="","",H43-J43)) -> 2 | L43: =IF(I43="","",IF(J43="","",I43-J43)) -> 1 | M43: =IF(J43="","—",IF(J43<1.5,"Amateur",IF(J43<2.5,"Collaborator",IF(J43<3.5,"Enabler",IF(J43<4.5,"Driving Force","Visionary"))))) -> Enabler | N43: =IF(J43="","—",IF(K43>0,"▼ Below Required",IF(K43=0,"✔ At Target","▲ Exceeds Target"))) -> ▼ Below Required
B44: 5.2 | C44: Financial Compliance & Resource Governance | D44: 1 | E44: 2 | F44: 4 | G44: 5 | H44: =IF($D$5="","",IF($D$5="In-charge / DM",D44,IF($D$5="Manager",E44,IF($D$5="Head",F44,IF($D$5="Chief",G44,""))))) -> 5 | I44: 4 | J44: 3 | K44: =IF(J44="","",IF(H44="","",H44-J44)) -> 2 | L44: =IF(I44="","",IF(J44="","",I44-J44)) -> 1 | M44: =IF(J44="","—",IF(J44<1.5,"Amateur",IF(J44<2.5,"Collaborator",IF(J44<3.5,"Enabler",IF(J44<4.5,"Driving Force","Visionary"))))) -> Enabler | N44: =IF(J44="","—",IF(K44>0,"▼ Below Required",IF(K44=0,"✔ At Target","▲ Exceeds Target"))) -> ▼ Below Required
B45: 5.3 | C45: Financial Automation & Optimization | D45: 3 | E45: 2 | F45: 5 | G45: 5 | H45: =IF($D$5="","",IF($D$5="In-charge / DM",D45,IF($D$5="Manager",E45,IF($D$5="Head",F45,IF($D$5="Chief",G45,""))))) -> 5 | I45: 4 | J45: 5 | K45: =IF(J45="","",IF(H45="","",H45-J45)) -> 0 | L45: =IF(I45="","",IF(J45="","",I45-J45)) -> -1 | M45: =IF(J45="","—",IF(J45<1.5,"Amateur",IF(J45<2.5,"Collaborator",IF(J45<3.5,"Enabler",IF(J45<4.5,"Driving Force","Visionary"))))) -> Visionary | N45: =IF(J45="","—",IF(K45>0,"▼ Below Required",IF(K45=0,"✔ At Target","▲ Exceeds Target"))) -> ✔ At Target
...

Sheet 📊 PM Family Summary
A1: PROJECT MANAGEMENT JOB FAMILY — COMPETENCY ASSESSMENT SUMMARY
A2: Required vs Current Competency Level | Scale 1–5 | 🟢 No Gap 🟡 Developing (Gap ≤ 1) 🟠 Needs Focus (Gap ≤ 2) 🔴 Critical (Gap > 2)
B4: # | C4: Employee Name | D4: Position | E4: Division | F4: Department | G4: Required Competency Level | H4: Current Competency Level | I4: Competency Gap | J4: Status | K4: Development Plan
B5: 1 | C5: Ahmed Raza | D5: Manager | E5: ISD | G5: 3.8 | H5: 3.1 | I5: =IFERROR(ROUND(G5-H5,1),"") -> 0.7 | J5: =IF(I5="","—",IF(I5<=0,"🟢 No Gap",IF(I5<=1,"🟡 Developing",IF(I5<=2,"🟠 Needs Focus","🔴 Critical")))) -> 🟡 Developing | K5: =IF(J5="🟢 No Gap","No Action Needed",IF(J5="🟡 Developing","Targeted Dev Plan",IF(J5="🟠 Needs Focus","Structured Dev Plan",IF(J5="🔴 Critical","Urgent Intervention","—")))) -> Targeted Dev Plan
B6: 2 | C6: Sara Qureshi | D6: Head | E6: IP | G6: 4.2 | H6: 4.2 | I6: =IFERROR(ROUND(G6-H6,1),"") -> 0 | J6: =IF(I6="","—",IF(I6<=0,"🟢 No Gap",IF(I6<=1,"🟡 Developing",IF(I6<=2,"🟠 Needs Focus","🔴 Critical")))) -> 🟢 No Gap | K6: =IF(J6="🟢 No Gap","No Action Needed",IF(J6="🟡 Developing","Targeted Dev Plan",IF(J6="🟠 Needs Focus","Structured Dev Plan",IF(J6="🔴 Critical","Urgent Intervention","—")))) -> No Action Needed
B7: 3 | C7: Bilal Khan | D7: In-charge/DM | E7: EPC | G7: 3 | H7: 1 | I7: =IFERROR(ROUND(G7-H7,1),"") -> 2 | J7: =IF(I7="","—",IF(I7<=0,"🟢 No Gap",IF(I7<=1,"🟡 Developing",IF(I7<=2,"🟠 Needs Focus","🔴 Critical")))) -> 🟠 Needs Focus | K7: =IF(J7="🟢 No Gap","No Action Needed",IF(J7="🟡 Developing","Targeted Dev Plan",IF(J7="🟠 Needs Focus","Structured Dev Plan",IF(J7="🔴 Critical","Urgent Intervention","—")))) -> Structured Dev Plan
B8: 4 | C8: Ayesha Noor | D8: Chief | E8: Corporate | G8: 4.5 | H8: 4.5 | I8: =IFERROR(ROUND(G8-H8,1),"") -> 0 | J8: =IF(I8="","—",IF(I8<=0,"🟢 No Gap",IF(I8<=1,"🟡 Developing",IF(I8<=2,"🟠 Needs Focus","🔴 Critical")))) -> 🟢 No Gap | K8: =IF(J8="🟢 No Gap","No Action Needed",IF(J8="🟡 Developing","Targeted Dev Plan",IF(J8="🟠 Needs Focus","Structured Dev Plan",IF(J8="🔴 Critical","Urgent Intervention","—")))) -> No Action Needed
B9: 5 | C9: Omar Farooq | D9: In-charge/DM | E9: Cluster | G9: 3 | H9: 1.6 | I9: =IFERROR(ROUND(G9-H9,1),"") -> 1.4 | J9: =IF(I9="","—",IF(I9<=0,"🟢 No Gap",IF(I9<=1,"🟡 Developing",IF(I9<=2,"🟠 Needs Focus","🔴 Critical")))) -> 🟠 Needs Focus | K9: =IF(J9="🟢 No Gap","No Action Needed",IF(J9="🟡 Developing","Targeted Dev Plan",IF(J9="🟠 Needs Focus","Structured Dev Plan",IF(J9="🔴 Critical","Urgent Intervention","—")))) -> Structured Dev Plan
B10: 6 | C10: Fatima Ali | D10: Head | E10: Construction | G10: 4.2 | H10: 3.4 | I10: =IFERROR(ROUND(G10-H10,1),"") -> 0.8 | J10: =IF(I10="","—",IF(I10<=0,"🟢 No Gap",IF(I10<=1,"🟡 Developing",IF(I10<=2,"🟠 Needs Focus","🔴 Critical")))) -> 🟡 Developing | K10: =IF(J10="🟢 No Gap","No Action Needed",IF(J10="🟡 Developing","Targeted Dev Plan",IF(J10="🟠 Needs Focus","Structured Dev Plan",IF(J10="🔴 Critical","Urgent Intervention","—")))) -> Targeted Dev Plan
B11: 7 | C11: Hamza Sheikh | D11: Manager | E11: ISD | G11: 3.8 | H11: 1.5 | I11: =IFERROR(ROUND(G11-H11,1),"") -> 2.3 | J11: =IF(I11="","—",IF(I11<=0,"🟢 No Gap",IF(I11<=1,"🟡 Developing",IF(I11<=2,"🟠 Needs Focus","🔴 Critical")))) -> 🔴 Critical | K11: =IF(J11="🟢 No Gap","No Action Needed",IF(J11="🟡 Developing","Targeted Dev Plan",IF(J11="🟠 Needs Focus","Structured Dev Plan",IF(J11="🔴 Critical","Urgent Intervention","—")))) -> Urgent Intervention
B12: 8 | C12: Zainab Malik | D12: Chief | E12: IP | G12: 4.5 | H12: 4.6 | I12: =IFERROR(ROUND(G12-H12,1),"") -> -0.1 | J12: =IF(I12="","—",IF(I12<=0,"🟢 No Gap",IF(I12<=1,"🟡 Developing",IF(I12<=2,"🟠 Needs Focus","🔴 Critical")))) -> 🟢 No Gap | K12: =IF(J12="🟢 No Gap","No Action Needed",IF(J12="🟡 Developing","Targeted Dev Plan",IF(J12="🟠 Needs Focus","Structured Dev Plan",IF(J12="🔴 Critical","Urgent Intervention","—")))) -> No Action Needed
B13: 9 | C13: Usman Tariq | D13: Manager | E13: EPC | G13: 3.8 | H13: 2.4 | I13: =IFERROR(ROUND(G13-H13,1),"") -> 1.4 | J13: =IF(I13="","—",IF(I13<=0,"🟢 No Gap",IF(I13<=1,"🟡 Developing",IF(I13<=2,"🟠 Needs Focus","🔴 Critical")))) -> 🟠 Needs Focus | K13: =IF(J13="🟢 No Gap","No Action Needed",IF(J13="🟡 Developing","Targeted Dev Plan",IF(J13="🟠 Needs Focus","Structured Dev Plan",IF(J13="🔴 Critical","Urgent Intervention","—")))) -> Structured Dev Plan
B14: 10 | C14: Nadia Iqbal | D14: Head | E14: Corporate | G14: 4.2 | H14: 3.5 | I14: =IFERROR(ROUND(G14-H14,1),"") -> 0.7 | J14: =IF(I14="","—",IF(I14<=0,"🟢 No Gap",IF(I14<=1,"🟡 Developing",IF(I14<=2,"🟠 Needs Focus","🔴 Critical")))) -> 🟡 Developing | K14: =IF(J14="🟢 No Gap","No Action Needed",IF(J14="🟡 Developing","Targeted Dev Plan",IF(J14="🟠 Needs Focus","Structured Dev Plan",IF(J14="🔴 Critical","Urgent Intervention","—")))) -> Targeted Dev Plan
B16: ★ PM FAMILY AVERAGE | G16: =ROUND(AVERAGE(G5:G14),1) -> 3.9 | H16: =ROUND(AVERAGE(H5:H14),1) -> 3 | I16: =IFERROR(ROUND(G16-H16,1),"") -> 0.9 | J16: =IF(I16<=0,"🟢 No Gap",IF(I16<=1,"🟡 Developing",IF(I16<=2,"🟠 Needs Focus","🔴 Critical"))) -> 🟡 Developing
B18: 📊 DIVISION-WISE COMPETENCY SUMMARY
B19: Division | C19: # Employees | D19: Required Competency Level | E19: Current Competency Level | F19: Competency Gap | G19: Status
B20: ISD | C20: =COUNTIF(E5:E14,"ISD") -> 2 | D20: =IFERROR(AVERAGEIF(E5:E14,"ISD",G5:G14),"") -> 3.8 | E20: =IFERROR(AVERAGEIF(E5:E14,"ISD",H5:H14),"") -> 2.3 | F20: =IFERROR(ROUND(D20-E20,1),"") -> 1.5 | G20: =IF(F20="","—",IF(F20<=0,"🟢 No Gap",IF(F20<=1,"🟡 Developing",IF(F20<=2,"🟠 Needs Focus","🔴 Critical")))) -> 🟠 Needs Focus
B21: IP | C21: =COUNTIF(E5:E14,"IP") -> 2 | D21: =IFERROR(AVERAGEIF(E5:E14,"IP",G5:G14),"") -> 4.35 | E21: =IFERROR(AVERAGEIF(E5:E14,"IP",H5:H14),"") -> 4.4 | F21: =IFERROR(ROUND(D21-E21,1),"") -> -0.1 | G21: =IF(F21="","—",IF(F21<=0,"🟢 No Gap",IF(F21<=1,"🟡 Developing",IF(F21<=2,"🟠 Needs Focus","🔴 Critical")))) -> 🟢 No Gap
B22: EPC | C22: =COUNTIF(E5:E14,"EPC") -> 2 | D22: =IFERROR(AVERAGEIF(E5:E14,"EPC",G5:G14),"") -> 3.4 | E22: =IFERROR(AVERAGEIF(E5:E14,"EPC",H5:H14),"") -> 1.7 | F22: =IFERROR(ROUND(D22-E22,1),"") -> 1.7 | G22: =IF(F22="","—",IF(F22<=0,"🟢 No Gap",IF(F22<=1,"🟡 Developing",IF(F22<=2,"🟠 Needs Focus","🔴 Critical")))) -> 🟠 Needs Focus
B23: Corporate | C23: =COUNTIF(E5:E14,"Corporate") -> 2 | D23: =IFERROR(AVERAGEIF(E5:E14,"Corporate",G5:G14),"") -> 4.35 | E23: =IFERROR(AVERAGEIF(E5:E14,"Corporate",H5:H14),"") -> 4 | F23: =IFERROR(ROUND(D23-E23,1),"") -> 0.4 | G23: =IF(F23="","—",IF(F23<=0,"🟢 No Gap",IF(F23<=1,"🟡 Developing",IF(F23<=2,"🟠 Needs Focus","🔴 Critical")))) -> 🟡 Developing
B24: Cluster | C24: =COUNTIF(E5:E14,"Cluster") -> 1 | D24: =IFERROR(AVERAGEIF(E5:E14,"Cluster",G5:G14),"") -> 3 | E24: =IFERROR(AVERAGEIF(E5:E14,"Cluster",H5:H14),"") -> 1.6 | F24: =IFERROR(ROUND(D24-E24,1),"") -> 1.4 | G24: =IF(F24="","—",IF(F24<=0,"🟢 No Gap",IF(F24<=1,"🟡 Developing",IF(F24<=2,"🟠 Needs Focus","🔴 Critical")))) -> 🟠 Needs Focus
B25: Construction | C25: =COUNTIF(E5:E14,"Construction") -> 1 | D25: =IFERROR(AVERAGEIF(E5:E14,"Construction",G5:G14),"") -> 4.2 | E25: =IFERROR(AVERAGEIF(E5:E14,"Construction",H5:H14),"") -> 3.4 | F25: =IFERROR(ROUND(D25-E25,1),"") -> 0.8 | G25: =IF(F25="","—",IF(F25<=0,"🟢 No Gap",IF(F25<=1,"🟡 Developing",IF(F25<=2,"🟠 Needs Focus","🔴 Critical")))) -> 🟡 Developing
B26: TOTAL / AVERAGE | C26: =SUM(C20:C25) -> 10 | D26: =ROUND(AVERAGE(D20:D25),1) -> 3.9 | E26: =ROUND(AVERAGE(E20:E25),1) -> 2.9 | F26: =IFERROR(ROUND(D26-E26,1),"") -> 1 | G26: =IF(F26<=0,"🟢 No Gap",IF(F26<=1,"🟡 Developing",IF(F26<=2,"🟠 Needs Focus","🔴 Critical"))) -> 🟡 Developing
B28: 📊 DESIGNATION-WISE COMPETENCY SUMMARY
B29: Designation | C29: # Employees | D29: Required Competency Level | E29: Current Competency Level | F29: Competency Gap | G29: Status
B30: In-charge/DM | C30: =COUNTIF(D5:D14,"In-charge/DM") -> 2 | D30: =IFERROR(AVERAGEIF(D5:D14,"In-charge/DM",G5:G14),"") -> 3 | E30: =IFERROR(AVERAGEIF(D5:D14,"In-charge/DM",H5:H14),"") -> 1.3 | F30: =IFERROR(ROUND(D30-E30,1),"") -> 1.7 | G30: =IF(F30="","—",IF(F30<=0,"🟢 No Gap",IF(F30<=1,"🟡 Developing",IF(F30<=2,"🟠 Needs Focus","🔴 Critical")))) -> 🟠 Needs Focus
B31: Manager | C31: =COUNTIF(D5:D14,"Manager") -> 3 | D31: =IFERROR(AVERAGEIF(D5:D14,"Manager",G5:G14),"") -> 3.8 | E31: =IFERROR(AVERAGEIF(D5:D14,"Manager",H5:H14),"") -> 2.3333333 | F31: =IFERROR(ROUND(D31-E31,1),"") -> 1.5 | G31: =IF(F31="","—",IF(F31<=0,"🟢 No Gap",IF(F31<=1,"🟡 Developing",IF(F31<=2,"🟠 Needs Focus","🔴 Critical")))) -> 🟠 Needs Focus
B32: Head | C32: =COUNTIF(D5:D14,"Head") -> 3 | D32: =IFERROR(AVERAGEIF(D5:D14,"Head",G5:G14),"") -> 4.2 | E32: =IFERROR(AVERAGEIF(D5:D14,"Head",H5:H14),"") -> 3.7 | F32: =IFERROR(ROUND(D32-E32,1),"") -> 0.5 | G32: =IF(F32="","—",IF(F32<=0,"🟢 No Gap",IF(F32<=1,"🟡 Developing",IF(F32<=2,"🟠 Needs Focus","🔴 Critical")))) -> 🟡 Developing
B33: Chief | C33: =COUNTIF(D5:D14,"Chief") -> 2 | D33: =IFERROR(AVERAGEIF(D5:D14,"Chief",G5:G14),"") -> 4.5 | E33: =IFERROR(AVERAGEIF(D5:D14,"Chief",H5:H14),"") -> 4.55 | F33: =IFERROR(ROUND(D33-E33,1),"") -> 0 | G33: =IF(F33="","—",IF(F33<=0,"🟢 No Gap",IF(F33<=1,"🟡 Developing",IF(F33<=2,"🟠 Needs Focus","🔴 Critical")))) -> 🟢 No Gap
B34: TOTAL / AVERAGE | C34: =SUM(C30:C33) -> 10 | D34: =ROUND(AVERAGE(D30:D33),1) -> 3.9 | E34: =ROUND(AVERAGE(E30:E33),1) -> 3 | F34: =IFERROR(ROUND(D34-E34,1),"") -> 0.9 | G34: =IF(F34<=0,"🟢 No Gap",IF(F34<=1,"🟡 Developing",IF(F34<=2,"🟠 Needs Focus","🔴 Critical"))) -> 🟡 Developing
B36: Division | C36: Required | D36: Current | E36: Gap
B37: ISD | C37: =IFERROR(AVERAGEIF(E5:E14,B37,G5:G14),0) -> 3.8 | D37: =IFERROR(AVERAGEIF(E5:E14,B37,H5:H14),0) -> 2.3 | E37: =IFERROR(C37-D37,0) -> 1.5
B38: IP | C38: =IFERROR(AVERAGEIF(E5:E14,B38,G5:G14),0) -> 4.35 | D38: =IFERROR(AVERAGEIF(E5:E14,B38,H5:H14),0) -> 4.4 | E38: =IFERROR(C38-D38,0) -> -0.05
B39: EPC | C39: =IFERROR(AVERAGEIF(E5:E14,B39,G5:G14),0) -> 3.4 | D39: =IFERROR(AVERAGEIF(E5:E14,B39,H5:H14),0) -> 1.7 | E39: =IFERROR(C39-D39,0) -> 1.7
B40: Corporate | C40: =IFERROR(AVERAGEIF(E5:E14,B40,G5:G14),0) -> 4.35 | D40: =IFERROR(AVERAGEIF(E5:E14,B40,H5:H14),0) -> 4 | E40: =IFERROR(C40-D40,0) -> 0.35
B41: Cluster | C41: =IFERROR(AVERAGEIF(E5:E14,B41,G5:G14),0) -> 3 | D41: =IFERROR(AVERAGEIF(E5:E14,B41,H5:H14),0) -> 1.6 | E41: =IFERROR(C41-D41,0) -> 1.4
B42: Construction | C42: =IFERROR(AVERAGEIF(E5:E14,B42,G5:G14),0) -> 4.2 | D42: =IFERROR(AVERAGEIF(E5:E14,B42,H5:H14),0) -> 3.4 | E42: =IFERROR(C42-D42,0) -> 0.8
B44: Designation | C44: Required | D44: Current | E44: Gap
B45: In-charge/DM | C45: =IFERROR(AVERAGEIF(D5:D14,B45,G5:G14),0) -> 3 | D45: =IFERROR(AVERAGEIF(D5:D14,B45,H5:H14),0) -> 1.3 | E45: =IFERROR(C45-D45,0) -> 1.7
B46: Manager | C46: =IFERROR(AVERAGEIF(D5:D14,B46,G5:G14),0) -> 3.8 | D46: =IFERROR(AVERAGEIF(D5:D14,B46,H5:H14),0) -> 2.3333333 | E46: =IFERROR(C46-D46,0) -> 1.4666667
...

Sheet 📈 Dashboard
A1: PROJECT MANAGEMENT COMPETENCY — MANAGEMENT DASHBOARD
A2: Competency Gap Analysis | PM Job Family | All figures on 1–5 scale
A4: Employees Assessed | C4: PM Family Required Competency Level | E4: PM Family Current Competency Level | G4: PM Family Competency Gap | I4: 🟡 Developing | K4: 🟠 Needs Focus
A5: =COUNTA('📊 PM Family Summary'!C5:C14) -> 10 | C5: =ROUND(AVERAGE('📊 PM Family Summary'!G5:G14),1) -> 3.9 | E5: =ROUND(AVERAGE('📊 PM Family Summary'!H5:H14),1) -> 3 | G5: =ROUND(C5-E5,1) -> 0.9 | I5: =COUNTIF('📊 PM Family Summary'!J5:J14,"🟡 Developing") -> 3 | K5: =COUNTIF('📊 PM Family Summary'!J5:J14,"🟠 Needs Focus") -> 3
A7: 🟢 No Gap | C7: 🔴 Critical
A8: =COUNTIF('📊 PM Family Summary'!J5:J14,"🟢 No Gap") -> 3 | C8: =COUNTIF('📊 PM Family Summary'!J5:J14,"🔴 Critical") -> 1
A10: 🚦 COMPETENCY GAP GUIDE
A11: 🟢 No Gap | C11: Gap = 0 | E11: Employee meets / exceeds all requirements. No action needed.
A12: 🟡 Developing | C12: Gap 0–1 | E12: Some gaps. Targeted individual development plan recommended.
A13: 🟠 Needs Focus | C13: Gap 1–2 | E13: Significant gaps. Structured development plan required.
A14: 🔴 Critical | C14: Gap > 2 | E14: Critical gaps. Urgent intervention and monitoring needed.
A16: 📋 EMPLOYEE COMPETENCY OVERVIEW
A17: # | B17: Employee | C17: Position | D17: Division | E17: Required Competency Level | F17: Current Competency Level | G17: Competency Gap | H17: Status | I17: Dev Plan
A18: 1 | B18: ='📊 PM Family Summary'!C5 -> Ahmed Raza | C18: ='📊 PM Family Summary'!D5 -> Manager | D18: ='📊 PM Family Summary'!E5 -> ISD | E18: ='📊 PM Family Summary'!G5 -> 3.8 | F18: ='📊 PM Family Summary'!H5 -> 3.1 | G18: ='📊 PM Family Summary'!I5 -> 0.7 | H18: ='📊 PM Family Summary'!J5 -> 🟡 Developing | I18: ='📊 PM Family Summary'!K5 -> Targeted Dev Plan
A19: 2 | B19: ='📊 PM Family Summary'!C6 -> Sara Qureshi | C19: ='📊 PM Family Summary'!D6 -> Head | D19: ='📊 PM Family Summary'!E6 -> IP | E19: ='📊 PM Family Summary'!G6 -> 4.2 | F19: ='📊 PM Family Summary'!H6 -> 4.2 | G19: ='📊 PM Family Summary'!I6 -> 0 | H19: ='📊 PM Family Summary'!J6 -> 🟢 No Gap | I19: ='📊 PM Family Summary'!K6 -> No Action Needed
A20: 3 | B20: ='📊 PM Family Summary'!C7 -> Bilal Khan | C20: ='📊 PM Family Summary'!D7 -> In-charge/DM | D20: ='📊 PM Family Summary'!E7 -> EPC | E20: ='📊 PM Family Summary'!G7 -> 3 | F20: ='📊 PM Family Summary'!H7 -> 1 | G20: ='📊 PM Family Summary'!I7 -> 2 | H20: ='📊 PM Family Summary'!J7 -> 🟠 Needs Focus | I20: ='📊 PM Family Summary'!K7 -> Structured Dev Plan
A21: 4 | B21: ='📊 PM Family Summary'!C8 -> Ayesha Noor | C21: ='📊 PM Family Summary'!D8 -> Chief | D21: ='📊 PM Family Summary'!E8 -> Corporate | E21: ='📊 PM Family Summary'!G8 -> 4.5 | F21: ='📊 PM Family Summary'!H8 -> 4.5 | G21: ='📊 PM Family Summary'!I8 -> 0 | H21: ='📊 PM Family Summary'!J8 -> 🟢 No Gap | I21: ='📊 PM Family Summary'!K8 -> No Action Needed
A22: 5 | B22: ='📊 PM Family Summary'!C9 -> Omar Farooq | C22: ='📊 PM Family Summary'!D9 -> In-charge/DM | D22: ='📊 PM Family Summary'!E9 -> Cluster | E22: ='📊 PM Family Summary'!G9 -> 3 | F22: ='📊 PM Family Summary'!H9 -> 1.6 | G22: ='📊 PM Family Summary'!I9 -> 1.4 | H22: ='📊 PM Family Summary'!J9 -> 🟠 Needs Focus | I22: ='📊 PM Family Summary'!K9 -> Structured Dev Plan
A23: 6 | B23: ='📊 PM Family Summary'!C10 -> Fatima Ali | C23: ='📊 PM Family Summary'!D10 -> Head | D23: ='📊 PM Family Summary'!E10 -> Construction | E23: ='📊 PM Family Summary'!G10 -> 4.2 | F23: ='📊 PM Family Summary'!H10 -> 3.4 | G23: ='📊 PM Family Summary'!I10 -> 0.8 | H23: ='📊 PM Family Summary'!J10 -> 🟡 Developing | I23: ='📊 PM Family Summary'!K10 -> Targeted Dev Plan
A24: 7 | B24: ='📊 PM Family Summary'!C11 -> Hamza Sheikh | C24: ='📊 PM Family Summary'!D11 -> Manager | D24: ='📊 PM Family Summary'!E11 -> ISD | E24: ='📊 PM Family Summary'!G11 -> 3.8 | F24: ='📊 PM Family Summary'!H11 -> 1.5 | G24: ='📊 PM Family Summary'!I11 -> 2.3 | H24: ='📊 PM Family Summary'!J11 -> 🔴 Critical | I24: ='📊 PM Family Summary'!K11 -> Urgent Intervention
A25: 8 | B25: ='📊 PM Family Summary'!C12 -> Zainab Malik | C25: ='📊 PM Family Summary'!D12 -> Chief | D25: ='📊 PM Family Summary'!E12 -> IP | E25: ='📊 PM Family Summary'!G12 -> 4.5 | F25: ='📊 PM Family Summary'!H12 -> 4.6 | G25: ='📊 PM Family Summary'!I12 -> -0.1 | H25: ='📊 PM Family Summary'!J12 -> 🟢 No Gap | I25: ='📊 PM Family Summary'!K12 -> No Action Needed
A26: 9 | B26: ='📊 PM Family Summary'!C13 -> Usman Tariq | C26: ='📊 PM Family Summary'!D13 -> Manager | D26: ='📊 PM Family Summary'!E13 -> EPC | E26: ='📊 PM Family Summary'!G13 -> 3.8 | F26: ='📊 PM Family Summary'!H13 -> 2.4 | G26: ='📊 PM Family Summary'!I13 -> 1.4 | H26: ='📊 PM Family Summary'!J13 -> 🟠 Needs Focus | I26: ='📊 PM Family Summary'!K13 -> Structured Dev Plan
A27: 10 | B27: ='📊 PM Family Summary'!C14 -> Nadia Iqbal | C27: ='📊 PM Family Summary'!D14 -> Head | D27: ='📊 PM Family Summary'!E14 -> Corporate | E27: ='📊 PM Family Summary'!G14 -> 4.2 | F27: ='📊 PM Family Summary'!H14 -> 3.5 | G27: ='📊 PM Family Summary'!I14 -> 0.7 | H27: ='📊 PM Family Summary'!J14 -> 🟡 Developing | I27: ='📊 PM Family Summary'!K14 -> Targeted Dev Plan
A29: Division | B29: Required | C29: Current | D29: Gap
A30: ISD | B30: =IFERROR(AVERAGEIF('📊 PM Family Summary'!E5:E14,A30,'📊 PM Family Summary'!G5:G14),0) -> 3.8 | C30: =IFERROR(AVERAGEIF('📊 PM Family Summary'!E5:E14,A30,'📊 PM Family Summary'!H5:H14),0) -> 2.3 | D30: =IFERROR(B30-C30,0) -> 1.5
A31: IP | B31: =IFERROR(AVERAGEIF('📊 PM Family Summary'!E5:E14,A31,'📊 PM Family Summary'!G5:G14),0) -> 4.35 | C31: =IFERROR(AVERAGEIF('📊 PM Family Summary'!E5:E14,A31,'📊 PM Family Summary'!H5:H14),0) -> 4.4 | D31: =IFERROR(B31-C31,0) -> -0.05
A32: EPC | B32: =IFERROR(AVERAGEIF('📊 PM Family Summary'!E5:E14,A32,'📊 PM Family Summary'!G5:G14),0) -> 3.4 | C32: =IFERROR(AVERAGEIF('📊 PM Family Summary'!E5:E14,A32,'📊 PM Family Summary'!H5:H14),0) -> 1.7 | D32: =IFERROR(B32-C32,0) -> 1.7
A33: Corporate | B33: =IFERROR(AVERAGEIF('📊 PM Family Summary'!E5:E14,A33,'📊 PM Family Summary'!G5:G14),0) -> 4.35 | C33: =IFERROR(AVERAGEIF('📊 PM Family Summary'!E5:E14,A33,'📊 PM Family Summary'!H5:H14),0) -> 4 | D33: =IFERROR(B33-C33,0) -> 0.35
A34: Cluster | B34: =IFERROR(AVERAGEIF('📊 PM Family Summary'!E5:E14,A34,'📊 PM Family Summary'!G5:G14),0) -> 3 | C34: =IFERROR(AVERAGEIF('📊 PM Family Summary'!E5:E14,A34,'📊 PM Family Summary'!H5:H14),0) -> 1.6 | D34: =IFERROR(B34-C34,0) -> 1.4
A35: Construction | B35: =IFERROR(AVERAGEIF('📊 PM Family Summary'!E5:E14,A35,'📊 PM Family Summary'!G5:G14),0) -> 4.2 | C35: =IFERROR(AVERAGEIF('📊 PM Family Summary'!E5:E14,A35,'📊 PM Family Summary'!H5:H14),0) -> 3.4 | D35: =IFERROR(B35-C35,0) -> 0.8
A37: Designation | B37: Required | C37: Current | D37: Gap
A38: In-charge/DM | B38: =IFERROR(AVERAGEIF('📊 PM Family Summary'!D5:D14,A38,'📊 PM Family Summary'!G5:G14),0) -> 3 | C38: =IFERROR(AVERAGEIF('📊 PM Family Summary'!D5:D14,A38,'📊 PM Family Summary'!H5:H14),0) -> 1.3 | D38: =IFERROR(B38-C38,0) -> 1.7
A39: Manager | B39: =IFERROR(AVERAGEIF('📊 PM Family Summary'!D5:D14,A39,'📊 PM Family Summary'!G5:G14),0) -> 3.8 | C39: =IFERROR(AVERAGEIF('📊 PM Family Summary'!D5:D14,A39,'📊 PM Family Summary'!H5:H14),0) -> 2.3333333 | D39: =IFERROR(B39-C39,0) -> 1.4666667
A40: Head | B40: =IFERROR(AVERAGEIF('📊 PM Family Summary'!D5:D14,A40,'📊 PM Family Summary'!G5:G14),0) -> 4.2 | C40: =IFERROR(AVERAGEIF('📊 PM Family Summary'!D5:D14,A40,'📊 PM Family Summary'!H5:H14),0) -> 3.7 | D40: =IFERROR(B40-C40,0) -> 0.5
A41: Chief | B41: =IFERROR(AVERAGEIF('📊 PM Family Summary'!D5:D14,A41,'📊 PM Family Summary'!G5:G14),0) -> 4.5 | C41: =IFERROR(AVERAGEIF('📊 PM Family Summary'!D5:D14,A41,'📊 PM Family Summary'!H5:H14),0) -> 4.55 | D41: =IFERROR(B41-C41,0) -> -0.05

Sheet 📑 PM Job Family Summary
A1: PM JOB FAMILY — COMPLETE COMPETENCY ASSESSMENT SUMMARY
A2: Consolidated view: All employees | Required vs Current Competency Level | Competency Gap | Scale 1–5
A4: SECTION A — INDIVIDUAL EMPLOYEE COMPETENCY TABLE
A5: # | B5: Employee Name | C5: Position | D5: Division | E5: Department | F5: Required Competency Level | G5: Current Competency Level | H5: Competency Gap | I5: Status | J5: Development Plan
A6: 1 | B6: ='📊 PM Family Summary'!C5 -> Ahmed Raza | C6: ='📊 PM Family Summary'!D5 -> Manager | D6: ='📊 PM Family Summary'!E5 -> ISD | E6: ='📊 PM Family Summary'!F5 -> 0 | F6: ='📊 PM Family Summary'!G5 -> 3.8 | G6: ='📊 PM Family Summary'!H5 -> 3.1 | H6: ='📊 PM Family Summary'!I5 -> 0.7 | I6: ='📊 PM Family Summary'!J5 -> 🟡 Developing | J6: ='📊 PM Family Summary'!K5 -> Targeted Dev Plan
A7: 2 | B7: ='📊 PM Family Summary'!C6 -> Sara Qureshi | C7: ='📊 PM Family Summary'!D6 -> Head | D7: ='📊 PM Family Summary'!E6 -> IP | E7: ='📊 PM Family Summary'!F6 -> 0 | F7: ='📊 PM Family Summary'!G6 -> 4.2 | G7: ='📊 PM Family Summary'!H6 -> 4.2 | H7: ='📊 PM Family Summary'!I6 -> 0 | I7: ='📊 PM Family Summary'!J6 -> 🟢 No Gap | J7: ='📊 PM Family Summary'!K6 -> No Action Needed
A8: 3 | B8: ='📊 PM Family Summary'!C7 -> Bilal Khan | C8: ='📊 PM Family Summary'!D7 -> In-charge/DM | D8: ='📊 PM Family Summary'!E7 -> EPC | E8: ='📊 PM Family Summary'!F7 -> 0 | F8: ='📊 PM Family Summary'!G7 -> 3 | G8: ='📊 PM Family Summary'!H7 -> 1 | H8: ='📊 PM Family Summary'!I7 -> 2 | I8: ='📊 PM Family Summary'!J7 -> 🟠 Needs Focus | J8: ='📊 PM Family Summary'!K7 -> Structured Dev Plan
A9: 4 | B9: ='📊 PM Family Summary'!C8 -> Ayesha Noor | C9: ='📊 PM Family Summary'!D8 -> Chief | D9: ='📊 PM Family Summary'!E8 -> Corporate | E9: ='📊 PM Family Summary'!F8 -> 0 | F9: ='📊 PM Family Summary'!G8 -> 4.5 | G9: ='📊 PM Family Summary'!H8 -> 4.5 | H9: ='📊 PM Family Summary'!I8 -> 0 | I9: ='📊 PM Family Summary'!J8 -> 🟢 No Gap | J9: ='📊 PM Family Summary'!K8 -> No Action Needed
A10: 5 | B10: ='📊 PM Family Summary'!C9 -> Omar Farooq | C10: ='📊 PM Family Summary'!D9 -> In-charge/DM | D10: ='📊 PM Family Summary'!E9 -> Cluster | E10: ='📊 PM Family Summary'!F9 -> 0 | F10: ='📊 PM Family Summary'!G9 -> 3 | G10: ='📊 PM Family Summary'!H9 -> 1.6 | H10: ='📊 PM Family Summary'!I9 -> 1.4 | I10: ='📊 PM Family Summary'!J9 -> 🟠 Needs Focus | J10: ='📊 PM Family Summary'!K9 -> Structured Dev Plan
A11: 6 | B11: ='📊 PM Family Summary'!C10 -> Fatima Ali | C11: ='📊 PM Family Summary'!D10 -> Head | D11: ='📊 PM Family Summary'!E10 -> Construction | E11: ='📊 PM Family Summary'!F10 -> 0 | F11: ='📊 PM Family Summary'!G10 -> 4.2 | G11: ='📊 PM Family Summary'!H10 -> 3.4 | H11: ='📊 PM Family Summary'!I10 -> 0.8 | I11: ='📊 PM Family Summary'!J10 -> 🟡 Developing | J11: ='📊 PM Family Summary'!K10 -> Targeted Dev Plan
A12: 7 | B12: ='📊 PM Family Summary'!C11 -> Hamza Sheikh | C12: ='📊 PM Family Summary'!D11 -> Manager | D12: ='📊 PM Family Summary'!E11 -> ISD | E12: ='📊 PM Family Summary'!F11 -> 0 | F12: ='📊 PM Family Summary'!G11 -> 3.8 | G12: ='📊 PM Family Summary'!H11 -> 1.5 | H12: ='📊 PM Family Summary'!I11 -> 2.3 | I12: ='📊 PM Family Summary'!J11 -> 🔴 Critical | J12: ='📊 PM Family Summary'!K11 -> Urgent Intervention
A13: 8 | B13: ='📊 PM Family Summary'!C12 -> Zainab Malik | C13: ='📊 PM Family Summary'!D12 -> Chief | D13: ='📊 PM Family Summary'!E12 -> IP | E13: ='📊 PM Family Summary'!F12 -> 0 | F13: ='📊 PM Family Summary'!G12 -> 4.5 | G13: ='📊 PM Family Summary'!H12 -> 4.6 | H13: ='📊 PM Family Summary'!I12 -> -0.1 | I13: ='📊 PM Family Summary'!J12 -> 🟢 No Gap | J13: ='📊 PM Family Summary'!K12 -> No Action Needed
A14: 9 | B14: ='📊 PM Family Summary'!C13 -> Usman Tariq | C14: ='📊 PM Family Summary'!D13 -> Manager | D14: ='📊 PM Family Summary'!E13 -> EPC | E14: ='📊 PM Family Summary'!F13 -> 0 | F14: ='📊 PM Family Summary'!G13 -> 3.8 | G14: ='📊 PM Family Summary'!H13 -> 2.4 | H14: ='📊 PM Family Summary'!I13 -> 1.4 | I14: ='📊 PM Family Summary'!J13 -> 🟠 Needs Focus | J14: ='📊 PM Family Summary'!K13 -> Structured Dev Plan
A15: 10 | B15: ='📊 PM Family Summary'!C14 -> Nadia Iqbal | C15: ='📊 PM Family Summary'!D14 -> Head | D15: ='📊 PM Family Summary'!E14 -> Corporate | E15: ='📊 PM Family Summary'!F14 -> 0 | F15: ='📊 PM Family Summary'!G14 -> 4.2 | G15: ='📊 PM Family Summary'!H14 -> 3.5 | H15: ='📊 PM Family Summary'!I14 -> 0.7 | I15: ='📊 PM Family Summary'!J14 -> 🟡 Developing | J15: ='📊 PM Family Summary'!K14 -> Targeted Dev Plan
A17: ★ AVERAGE | F17: =ROUND(AVERAGE(F6:F15),1) -> 3.9 | G17: =ROUND(AVERAGE(G6:G15),1) -> 3 | H17: =ROUND(F17-G17,1) -> 0.9 | I17: =IF(H17<=0,"🟢 No Gap",IF(H17<=1,"🟡 Developing",IF(H17<=2,"🟠 Needs Focus","🔴 Critical"))) -> 🟡 Developing
A20: SECTION B — COMPETENCY CATEGORY DISTRIBUTION
A21: Category | B21: Count | C21: % of Total | D21: Action Required
A22: 🟢 No Gap | B22: =COUNTIF('📊 PM Family Summary'!J5:J14,"🟢 No Gap") -> 3 | C22: =IFERROR(ROUND(B22/10*100,0)&"%","") -> 30% | D22: No Action Needed
A23: 🟡 Developing | B23: =COUNTIF('📊 PM Family Summary'!J5:J14,"🟡 Developing") -> 3 | C23: =IFERROR(ROUND(B23/10*100,0)&"%","") -> 30% | D23: Targeted Dev Plan
A24: 🟠 Needs Focus | B24: =COUNTIF('📊 PM Family Summary'!J5:J14,"🟠 Needs Focus") -> 3 | C24: =IFERROR(ROUND(B24/10*100,0)&"%","") -> 30% | D24: Structured Dev Plan
A25: 🔴 Critical | B25: =COUNTIF('📊 PM Family Summary'!J5:J14,"🔴 Critical") -> 1 | C25: =IFERROR(ROUND(B25/10*100,0)&"%","") -> 10% | D25: Urgent Intervention
A28: SECTION C — DIVISION-WISE COMPETENCY SUMMARY
A29: Division | B29: # Employees | C29: Required Competency Level | D29: Current Competency Level | E29: Competency Gap | F29: Status | G29: Development Action
A30: ISD | B30: =IFERROR(COUNTIF('📊 PM Family Summary'!E5:E14,"ISD"),"") -> 2 | C30: =IFERROR(ROUND(AVERAGEIF('📊 PM Family Summary'!E5:E14,"ISD",'📊 PM Family Summary'!G5:G14),1),"") -> 3.8 | D30: =IFERROR(ROUND(AVERAGEIF('📊 PM Family Summary'!E5:E14,"ISD",'📊 PM Family Summary'!H5:H14),1),"") -> 2.3 | E30: =IFERROR(ROUND(C30-D30,1),"") -> 1.5 | F30: =IF(E30="","—",IF(E30<=0,"🟢 No Gap",IF(E30<=1,"🟡 Developing",IF(E30<=2,"🟠 Needs Focus","🔴 Critical")))) -> 🟠 Needs Focus | G30: =IF(F30="🟢 No Gap","No Action",IF(F30="🟡 Developing","Targeted Plan",IF(F30="🟠 Needs Focus","Structured Plan","Urgent Intervention"))) -> Structured Plan
A31: IP | B31: =IFERROR(COUNTIF('📊 PM Family Summary'!E5:E14,"IP"),"") -> 2 | C31: =IFERROR(ROUND(AVERAGEIF('📊 PM Family Summary'!E5:E14,"IP",'📊 PM Family Summary'!G5:G14),1),"") -> 4.4 | D31: =IFERROR(ROUND(AVERAGEIF('📊 PM Family Summary'!E5:E14,"IP",'📊 PM Family Summary'!H5:H14),1),"") -> 4.4 | E31: =IFERROR(ROUND(C31-D31,1),"") -> 0 | F31: =IF(E31="","—",IF(E31<=0,"🟢 No Gap",IF(E31<=1,"🟡 Developing",IF(E31<=2,"🟠 Needs Focus","🔴 Critical")))) -> 🟢 No Gap | G31: =IF(F31="🟢 No Gap","No Action",IF(F31="🟡 Developing","Targeted Plan",IF(F31="🟠 Needs Focus","Structured Plan","Urgent Intervention"))) -> No Action
A32: EPC | B32: =IFERROR(COUNTIF('📊 PM Family Summary'!E5:E14,"EPC"),"") -> 2 | C32: =IFERROR(ROUND(AVERAGEIF('📊 PM Family Summary'!E5:E14,"EPC",'📊 PM Family Summary'!G5:G14),1),"") -> 3.4 | D32: =IFERROR(ROUND(AVERAGEIF('📊 PM Family Summary'!E5:E14,"EPC",'📊 PM Family Summary'!H5:H14),1),"") -> 1.7 | E32: =IFERROR(ROUND(C32-D32,1),"") -> 1.7 | F32: =IF(E32="","—",IF(E32<=0,"🟢 No Gap",IF(E32<=1,"🟡 Developing",IF(E32<=2,"🟠 Needs Focus","🔴 Critical")))) -> 🟠 Needs Focus | G32: =IF(F32="🟢 No Gap","No Action",IF(F32="🟡 Developing","Targeted Plan",IF(F32="🟠 Needs Focus","Structured Plan","Urgent Intervention"))) -> Structured Plan
A33: Corporate | B33: =IFERROR(COUNTIF('📊 PM Family Summary'!E5:E14,"Corporate"),"") -> 2 | C33: =IFERROR(ROUND(AVERAGEIF('📊 PM Family Summary'!E5:E14,"Corporate",'📊 PM Family Summary'!G5:G14),1),"") -> 4.4 | D33: =IFERROR(ROUND(AVERAGEIF('📊 PM Family Summary'!E5:E14,"Corporate",'📊 PM Family Summary'!H5:H14),1),"") -> 4 | E33: =IFERROR(ROUND(C33-D33,1),"") -> 0.4 | F33: =IF(E33="","—",IF(E33<=0,"🟢 No Gap",IF(E33<=1,"🟡 Developing",IF(E33<=2,"🟠 Needs Focus","🔴 Critical")))) -> 🟡 Developing | G33: =IF(F33="🟢 No Gap","No Action",IF(F33="🟡 Developing","Targeted Plan",IF(F33="🟠 Needs Focus","Structured Plan","Urgent Intervention"))) -> Targeted Plan
A34: Cluster | B34: =IFERROR(COUNTIF('📊 PM Family Summary'!E5:E14,"Cluster"),"") -> 1 | C34: =IFERROR(ROUND(AVERAGEIF('📊 PM Family Summary'!E5:E14,"Cluster",'📊 PM Family Summary'!G5:G14),1),"") -> 3 | D34: =IFERROR(ROUND(AVERAGEIF('📊 PM Family Summary'!E5:E14,"Cluster",'📊 PM Family Summary'!H5:H14),1),"") -> 1.6 | E34: =IFERROR(ROUND(C34-D34,1),"") -> 1.4 | F34: =IF(E34="","—",IF(E34<=0,"🟢 No Gap",IF(E34<=1,"🟡 Developing",IF(E34<=2,"🟠 Needs Focus","🔴 Critical")))) -> 🟠 Needs Focus | G34: =IF(F34="🟢 No Gap","No Action",IF(F34="🟡 Developing","Targeted Plan",IF(F34="🟠 Needs Focus","Structured Plan","Urgent Intervention"))) -> Structured Plan
A35: Construction | B35: =IFERROR(COUNTIF('📊 PM Family Summary'!E5:E14,"Construction"),"") -> 1 | C35: =IFERROR(ROUND(AVERAGEIF('📊 PM Family Summary'!E5:E14,"Construction",'📊 PM Family Summary'!G5:G14),1),"") -> 4.2 | D35: =IFERROR(ROUND(AVERAGEIF('📊 PM Family Summary'!E5:E14,"Construction",'📊 PM Family Summary'!H5:H14),1),"") -> 3.4 | E35: =IFERROR(ROUND(C35-D35,1),"") -> 0.8 | F35: =IF(E35="","—",IF(E35<=0,"🟢 No Gap",IF(E35<=1,"🟡 Developing",IF(E35<=2,"🟠 Needs Focus","🔴 Critical")))) -> 🟡 Developing | G35: =IF(F35="🟢 No Gap","No Action",IF(F35="🟡 Developing","Targeted Plan",IF(F35="🟠 Needs Focus","Structured Plan","Urgent Intervention"))) -> Targeted Plan
A38: SECTION D — DESIGNATION-WISE COMPETENCY SUMMARY
A39: Designation | B39: # Employees | C39: Required Competency Level | D39: Current Competency Level | E39: Competency Gap | F39: Status | G39: Development Action
A40: In-charge/DM | B40: =IFERROR(COUNTIF('📊 PM Family Summary'!D5:D14,"In-charge/DM"),"") -> 2 | C40: =IFERROR(ROUND(AVERAGEIF('📊 PM Family Summary'!D5:D14,"In-charge/DM",'📊 PM Family Summary'!G5:G14),1),"") -> 3 | D40: =IFERROR(ROUND(AVERAGEIF('📊 PM Family Summary'!D5:D14,"In-charge/DM",'📊 PM Family Summary'!H5:H14),1),"") -> 1.3 | E40: =IFERROR(ROUND(C40-D40,1),"") -> 1.7 | F40: =IF(E40="","—",IF(E40<=0,"🟢 No Gap",IF(E40<=1,"🟡 Developing",IF(E40<=2,"🟠 Needs Focus","🔴 Critical")))) -> 🟠 Needs Focus | G40: =IF(F40="🟢 No Gap","No Action",IF(F40="🟡 Developing","Targeted Plan",IF(F40="🟠 Needs Focus","Structured Plan","Urgent Intervention"))) -> Structured Plan
A41: Manager | B41: =IFERROR(COUNTIF('📊 PM Family Summary'!D5:D14,"Manager"),"") -> 3 | C41: =IFERROR(ROUND(AVERAGEIF('📊 PM Family Summary'!D5:D14,"Manager",'📊 PM Family Summary'!G5:G14),1),"") -> 3.8 | D41: =IFERROR(ROUND(AVERAGEIF('📊 PM Family Summary'!D5:D14,"Manager",'📊 PM Family Summary'!H5:H14),1),"") -> 2.3 | E41: =IFERROR(ROUND(C41-D41,1),"") -> 1.5 | F41: =IF(E41="","—",IF(E41<=0,"🟢 No Gap",IF(E41<=1,"🟡 Developing",IF(E41<=2,"🟠 Needs Focus","🔴 Critical")))) -> 🟠 Needs Focus | G41: =IF(F41="🟢 No Gap","No Action",IF(F41="🟡 Developing","Targeted Plan",IF(F41="🟠 Needs Focus","Structured Plan","Urgent Intervention"))) -> Structured Plan
A42: Head | B42: =IFERROR(COUNTIF('📊 PM Family Summary'!D5:D14,"Head"),"") -> 3 | C42: =IFERROR(ROUND(AVERAGEIF('📊 PM Family Summary'!D5:D14,"Head",'📊 PM Family Summary'!G5:G14),1),"") -> 4.2 | D42: =IFERROR(ROUND(AVERAGEIF('📊 PM Family Summary'!D5:D14,"Head",'📊 PM Family Summary'!H5:H14),1),"") -> 3.7 | E42: =IFERROR(ROUND(C42-D42,1),"") -> 0.5 | F42: =IF(E42="","—",IF(E42<=0,"🟢 No Gap",IF(E42<=1,"🟡 Developing",IF(E42<=2,"🟠 Needs Focus","🔴 Critical")))) -> 🟡 Developing | G42: =IF(F42="🟢 No Gap","No Action",IF(F42="🟡 Developing","Targeted Plan",IF(F42="🟠 Needs Focus","Structured Plan","Urgent Intervention"))) -> Targeted Plan
A43: Chief | B43: =IFERROR(COUNTIF('📊 PM Family Summary'!D5:D14,"Chief"),"") -> 2 | C43: =IFERROR(ROUND(AVERAGEIF('📊 PM Family Summary'!D5:D14,"Chief",'📊 PM Family Summary'!G5:G14),1),"") -> 4.5 | D43: =IFERROR(ROUND(AVERAGEIF('📊 PM Family Summary'!D5:D14,"Chief",'📊 PM Family Summary'!H5:H14),1),"") -> 4.6 | E43: =IFERROR(ROUND(C43-D43,1),"") -> -0.1 | F43: =IF(E43="","—",IF(E43<=0,"🟢 No Gap",IF(E43<=1,"🟡 Developing",IF(E43<=2,"🟠 Needs Focus","🔴 Critical")))) -> 🟢 No Gap | G43: =IF(F43="🟢 No Gap","No Action",IF(F43="🟡 Developing","Targeted Plan",IF(F43="🟠 Needs Focus","Structured Plan","Urgent Intervention"))) -> No Action
